Workbook

Sheet 값
B1: 사모벤처 | L1: 부동산 | R1: 인프라
B2: Buyout | C2: Growth | D2: Venture Capital | E2: Fund of Fund | F2: Long-term Core | G2: GP-Stake / Continuation Vehicle | H2: Senior Credit | I2: Junior Credit | J2: 국내 사모투자 | K2: Hedge Fund | L2: Core RE Equity | M2: Non-Core RE Equity | N2: 국내 부동산 | O2: Core RE Debt | P2: Non-Core RE Debt | Q2: Listed RE | R2: Core 국내 인프라 | S2: Non-Core 국내 인프라 | T2: Core 해외 인프라 | U2: Non-Core 해외 인프라 | V2: Super-Core Infrastructure
A3: 날짜 | B3: Burgiss Buyout Index | C3: Burgiss Venture Capital Index | D3: Burgiss Venture Capital Index | E3: Burgiss FoF Secondary Equity Index | F3: Burgiss FoF Primary Equity Index | G3: Burgiss FoF Secondary Equity Index | H3: Burgiss Senior Loan Index | I3: Burgiss Mezzanine Index | J3: Burgiss Equity Index (Asia & Pacific) | K3: HFRI FoF: Conservative Index | L3: MSCI Global Property Fund Index | M3: Burgiss Real Estate Equity Index (value-add, Opportunistic) | N3: MSCI Global Property Fund Index | O3: Giliberto-Levy Commercial Mortgage Performance Index (G-L 1) | P3: Giliberto-Levy High-Yield Real Estate Debt Index (G-L 2) | Q3: FTSE EPRA/NAREIT Developed Index | R3: Burgiss Infrastructure Equity Index (Core) | S3: Burgiss Infrastructure Equity Index (Core) | T3: Burgiss Infrastructure Equity Index (Core) | U3: Burgiss Infrastructure Equity Index (Core) | V3: FTSE Fixed Income Core Infrastrue Index
A4: 36616 | B4: =VLOOKUP($A4,[1]Burgiss_Return!$B:$P,MATCH(B$2,[1]Burgiss_Return!$B$5:$P$5,0),0) -> 0.1103 | C4: =VLOOKUP($A4,[1]Burgiss_Return!$B:$P,MATCH(C$2,[1]Burgiss_Return!$B$5:$P$5,0),0) -> 0.1533 | D4: =VLOOKUP($A4,[1]Burgiss_Return!$B:$P,MATCH(D$2,[1]Burgiss_Return!$B$5:$P$5,0),0) -> 0.1533 | F4: =VLOOKUP($A4,[1]Burgiss_Return!$B:$P,MATCH(F$2,[1]Burgiss_Return!$B$5:$P$5,0),0) -> 0.0053 | I4: =VLOOKUP($A4,[1]Burgiss_Return!$B:$P,MATCH(I$2,[1]Burgiss_Return!$B$5:$P$5,0),0) -> 0.0114 | J4: =VLOOKUP($A4,[1]Burgiss_Return!$B:$P,MATCH(J$2,[1]Burgiss_Return!$B$5:$P$5,0),0) -> 0.0383 | K4: 0.048656061 | M4: =VLOOKUP($A4,[1]Burgiss_Return!$B:$P,MATCH(M$2,[1]Burgiss_Return!$B$5:$P$5,0),0) -> 0.0334 | Q4: -0.0248
A5: 36707 | B5: =VLOOKUP($A5,[1]Burgiss_Return!$B:$P,MATCH(B$2,[1]Burgiss_Return!$B$5:$P$5,0),0) -> -0.0009 | C5: =VLOOKUP($A5,[1]Burgiss_Return!$B:$P,MATCH(C$2,[1]Burgiss_Return!$B$5:$P$5,0),0) -> 0.0751 | D5: =VLOOKUP($A5,[1]Burgiss_Return!$B:$P,MATCH(D$2,[1]Burgiss_Return!$B$5:$P$5,0),0) -> 0.0751 | F5: =VLOOKUP($A5,[1]Burgiss_Return!$B:$P,MATCH(F$2,[1]Burgiss_Return!$B$5:$P$5,0),0) -> 0.0363 | I5: =VLOOKUP($A5,[1]Burgiss_Return!$B:$P,MATCH(I$2,[1]Burgiss_Return!$B$5:$P$5,0),0) -> 0.0159 | J5: =VLOOKUP($A5,[1]Burgiss_Return!$B:$P,MATCH(J$2,[1]Burgiss_Return!$B$5:$P$5,0),0) -> -0.0852 | K5: -0.0055559234 | M5: =VLOOKUP($A5,[1]Burgiss_Return!$B:$P,MATCH(M$2,[1]Burgiss_Return!$B$5:$P$5,0),0) -> 0.0566 | Q5: 0.03609516
A6: 36799 | B6: =VLOOKUP($A6,[1]Burgiss_Return!$B:$P,MATCH(B$2,[1]Burgiss_Return!$B$5:$P$5,0),0) -> -0.0295 | C6: =VLOOKUP($A6,[1]Burgiss_Return!$B:$P,MATCH(C$2,[1]Burgiss_Return!$B$5:$P$5,0),0) -> 0.1497 | D6: =VLOOKUP($A6,[1]Burgiss_Return!$B:$P,MATCH(D$2,[1]Burgiss_Return!$B$5:$P$5,0),0) -> 0.1497 | F6: =VLOOKUP($A6,[1]Burgiss_Return!$B:$P,MATCH(F$2,[1]Burgiss_Return!$B$5:$P$5,0),0) -> 0.0089 | I6: =VLOOKUP($A6,[1]Burgiss_Return!$B:$P,MATCH(I$2,[1]Burgiss_Return!$B$5:$P$5,0),0) -> 0.0368 | J6: =VLOOKUP($A6,[1]Burgiss_Return!$B:$P,MATCH(J$2,[1]Burgiss_Return!$B$5:$P$5,0),0) -> -0.0453 | K6: 0.0085359625 | M6: =VLOOKUP($A6,[1]Burgiss_Return!$B:$P,MATCH(M$2,[1]Burgiss_Return!$B$5:$P$5,0),0) -> 0.0114 | Q6: 0.074871338
A7: 36891 | B7: =VLOOKUP($A7,[1]Burgiss_Return!$B:$P,MATCH(B$2,[1]Burgiss_Return!$B$5:$P$5,0),0) -> -0.0306 | C7: =VLOOKUP($A7,[1]Burgiss_Return!$B:$P,MATCH(C$2,[1]Burgiss_Return!$B$5:$P$5,0),0) -> -0.1013 | D7: =VLOOKUP($A7,[1]Burgiss_Return!$B:$P,MATCH(D$2,[1]Burgiss_Return!$B$5:$P$5,0),0) -> -0.1013 | F7: =VLOOKUP($A7,[1]Burgiss_Return!$B:$P,MATCH(F$2,[1]Burgiss_Return!$B$5:$P$5,0),0) -> -0.0575 | I7: =VLOOKUP($A7,[1]Burgiss_Return!$B:$P,MATCH(I$2,[1]Burgiss_Return!$B$5:$P$5,0),0) -> -0.0183 | J7: =VLOOKUP($A7,[1]Burgiss_Return!$B:$P,MATCH(J$2,[1]Burgiss_Return!$B$5:$P$5,0),0) -> -0.0729 | K7: 0.0056814788 | M7: =VLOOKUP($A7,[1]Burgiss_Return!$B:$P,MATCH(M$2,[1]Burgiss_Return!$B$5:$P$5,0),0) -> 0.0666 | Q7: 0.048211408
A8: 36981 | B8: =VLOOKUP($A8,[1]Burgiss_Return!$B:$P,MATCH(B$2,[1]Burgiss_Return!$B$5:$P$5,0),0) -> -0.0635 | C8: =VLOOKUP($A8,[1]Burgiss_Return!$B:$P,MATCH(C$2,[1]Burgiss_Return!$B$5:$P$5,0),0) -> -0.0899 | D8: =VLOOKUP($A8,[1]Burgiss_Return!$B:$P,MATCH(D$2,[1]Burgiss_Return!$B$5:$P$5,0),0) -> -0.0899 | F8: =VLOOKUP($A8,[1]Burgiss_Return!$B:$P,MATCH(F$2,[1]Burgiss_Return!$B$5:$P$5,0),0) -> -0.0119 | I8: =VLOOKUP($A8,[1]Burgiss_Return!$B:$P,MATCH(I$2,[1]Burgiss_Return!$B$5:$P$5,0),0) -> 0.0647 | J8: =VLOOKUP($A8,[1]Burgiss_Return!$B:$P,MATCH(J$2,[1]Burgiss_Return!$B$5:$P$5,0),0) -> 0.0091 | K8: 0.0019250338 | M8: =VLOOKUP($A8,[1]Burgiss_Return!$B:$P,MATCH(M$2,[1]Burgiss_Return!$B$5:$P$5,0),0) -> 0.0312 | Q8: -0.050465122
A9: 37072 | B9: =VLOOKUP($A9,[1]Burgiss_Return!$B:$P,MATCH(B$2,[1]Burgiss_Return!$B$5:$P$5,0),0) -> 0.0238 | C9: =VLOOKUP($A9,[1]Burgiss_Return!$B:$P,MATCH(C$2,[1]Burgiss_Return!$B$5:$P$5,0),0) -> -0.0746 | D9: =VLOOKUP($A9,[1]Burgiss_Return!$B:$P,MATCH(D$2,[1]Burgiss_Return!$B$5:$P$5,0),0) -> -0.0746 | F9: =VLOOKUP($A9,[1]Burgiss_Return!$B:$P,MATCH(F$2,[1]Burgiss_Return!$B$5:$P$5,0),0) -> -0.0608 | I9: =VLOOKUP($A9,[1]Burgiss_Return!$B:$P,MATCH(I$2,[1]Burgiss_Return!$B$5:$P$5,0),0) -> 0.029 | J9: =VLOOKUP($A9,[1]Burgiss_Return!$B:$P,MATCH(J$2,[1]Burgiss_Return!$B$5:$P$5,0),0) -> -0.013 | K9: 0.015350924 | M9: =VLOOKUP($A9,[1]Burgiss_Return!$B:$P,MATCH(M$2,[1]Burgiss_Return!$B$5:$P$5,0),0) -> 0.0007 | Q9: 0.060150237
A10: 37164 | B10: =VLOOKUP($A10,[1]Burgiss_Return!$B:$P,MATCH(B$2,[1]Burgiss_Return!$B$5:$P$5,0),0) -> -0.0809 | C10: =VLOOKUP($A10,[1]Burgiss_Return!$B:$P,MATCH(C$2,[1]Burgiss_Return!$B$5:$P$5,0),0) -> -0.1505 | D10: =VLOOKUP($A10,[1]Burgiss_Return!$B:$P,MATCH(D$2,[1]Burgiss_Return!$B$5:$P$5,0),0) -> -0.1505 | F10: =VLOOKUP($A10,[1]Burgiss_Return!$B:$P,MATCH(F$2,[1]Burgiss_Return!$B$5:$P$5,0),0) -> -0.0545 | I10: =VLOOKUP($A10,[1]Burgiss_Return!$B:$P,MATCH(I$2,[1]Burgiss_Return!$B$5:$P$5,0),0) -> 0.0149 | J10: =VLOOKUP($A10,[1]Burgiss_Return!$B:$P,MATCH(J$2,[1]Burgiss_Return!$B$5:$P$5,0),0) -> -0.0254 | K10: -0.0009217345 | M10: =VLOOKUP($A10,[1]Burgiss_Return!$B:$P,MATCH(M$2,[1]Burgiss_Return!$B$5:$P$5,0),0) -> -0.0062 | Q10: -0.098300145
A11: 37256 | B11: =VLOOKUP($A11,[1]Burgiss_Return!$B:$P,MATCH(B$2,[1]Burgiss_Return!$B$5:$P$5,0),0) -> -0.0011 | C11: =VLOOKUP($A11,[1]Burgiss_Return!$B:$P,MATCH(C$2,[1]Burgiss_Return!$B$5:$P$5,0),0) -> -0.0779 | D11: =VLOOKUP($A11,[1]Burgiss_Return!$B:$P,MATCH(D$2,[1]Burgiss_Return!$B$5:$P$5,0),0) -> -0.0779 | F11: =VLOOKUP($A11,[1]Burgiss_Return!$B:$P,MATCH(F$2,[1]Burgiss_Return!$B$5:$P$5,0),0) -> -0.0812 | I11: =VLOOKUP($A11,[1]Burgiss_Return!$B:$P,MATCH(I$2,[1]Burgiss_Return!$B$5:$P$5,0),0) -> 0.021 | J11: =VLOOKUP($A11,[1]Burgiss_Return!$B:$P,MATCH(J$2,[1]Burgiss_Return!$B$5:$P$5,0),0) -> -0.0637 | K11: 0.014464422 | M11: =VLOOKUP($A11,[1]Burgiss_Return!$B:$P,MATCH(M$2,[1]Burgiss_Return!$B$5:$P$5,0),0) -> 0.0367 | Q11: 0.059738902
A12: 37346 | B12: =VLOOKUP($A12,[1]Burgiss_Return!$B:$P,MATCH(B$2,[1]Burgiss_Return!$B$5:$P$5,0),0) -> -0.0023 | C12: =VLOOKUP($A12,[1]Burgiss_Return!$B:$P,MATCH(C$2,[1]Burgiss_Return!$B$5:$P$5,0),0) -> -0.0948 | D12: =VLOOKUP($A12,[1]Burgiss_Return!$B:$P,MATCH(D$2,[1]Burgiss_Return!$B$5:$P$5,0),0) -> -0.0948 | E12: =VLOOKUP($A12,[1]Burgiss_Return!$B:$P,MATCH(E$2,[1]Burgiss_Return!$B$5:$P$5,0),0) -> 0.0327 | F12: =VLOOKUP($A12,[1]Burgiss_Return!$B:$P,MATCH(F$2,[1]Burgiss_Return!$B$5:$P$5,0),0) -> -0.025 | G12: =VLOOKUP($A12,[1]Burgiss_Return!$B:$P,MATCH(G$2,[1]Burgiss_Return!$B$5:$P$5,0),0) -> 0.0327 | I12: =VLOOKUP($A12,[1]Burgiss_Return!$B:$P,MATCH(I$2,[1]Burgiss_Return!$B$5:$P$5,0),0) -> 0.0377 | J12: =VLOOKUP($A12,[1]Burgiss_Return!$B:$P,MATCH(J$2,[1]Burgiss_Return!$B$5:$P$5,0),0) -> 0.0141 | K12: 0.013385806 | M12: =VLOOKUP($A12,[1]Burgiss_Return!$B:$P,MATCH(M$2,[1]Burgiss_Return!$B$5:$P$5,0),0) -> 0.0143 | Q12: 0.053759611
A13: 37437 | B13: =VLOOKUP($A13,[1]Burgiss_Return!$B:$P,MATCH(B$2,[1]Burgiss_Return!$B$5:$P$5,0),0) -> -0.0135 | C13: =VLOOKUP($A13,[1]Burgiss_Return!$B:$P,MATCH(C$2,[1]Burgiss_Return!$B$5:$P$5,0),0) -> -0.1303 | D13: =VLOOKUP($A13,[1]Burgiss_Return!$B:$P,MATCH(D$2,[1]Burgiss_Return!$B$5:$P$5,0),0) -> -0.1303 | E13: =VLOOKUP($A13,[1]Burgiss_Return!$B:$P,MATCH(E$2,[1]Burgiss_Return!$B$5:$P$5,0),0) -> 0.0174 | F13: =VLOOKUP($A13,[1]Burgiss_Return!$B:$P,MATCH(F$2,[1]Burgiss_Return!$B$5:$P$5,0),0) -> -0.0711 | G13: =VLOOKUP($A13,[1]Burgiss_Return!$B:$P,MATCH(G$2,[1]Burgiss_Return!$B$5:$P$5,0),0) -> 0.0174 | I13: =VLOOKUP($A13,[1]Burgiss_Return!$B:$P,MATCH(I$2,[1]Burgiss_Return!$B$5:$P$5,0),0) -> -0.001 | J13: =VLOOKUP($A13,[1]Burgiss_Return!$B:$P,MATCH(J$2,[1]Burgiss_Return!$B$5:$P$5,0),0) -> -0.0505 | K13: 0.0065079412 | M13: =VLOOKUP($A13,[1]Burgiss_Return!$B:$P,MATCH(M$2,[1]Burgiss_Return!$B$5:$P$5,0),0) -> -0.0043 | Q13: 0.054388048
A14: 37529 | B14: =VLOOKUP($A14,[1]Burgiss_Return!$B:$P,MATCH(B$2,[1]Burgiss_Return!$B$5:$P$5,0),0) -> -0.0398 | C14: =VLOOKUP($A14,[1]Burgiss_Return!$B:$P,MATCH(C$2,[1]Burgiss_Return!$B$5:$P$5,0),0) -> -0.0991 | D14: =VLOOKUP($A14,[1]Burgiss_Return!$B:$P,MATCH(D$2,[1]Burgiss_Return!$B$5:$P$5,0),0) -> -0.0991 | E14: =VLOOKUP($A14,[1]Burgiss_Return!$B:$P,MATCH(E$2,[1]Burgiss_Return!$B$5:$P$5,0),0) -> -0.0334 | F14: =VLOOKUP($A14,[1]Burgiss_Return!$B:$P,MATCH(F$2,[1]Burgiss_Return!$B$5:$P$5,0),0) -> -0.0593 | G14: =VLOOKUP($A14,[1]Burgiss_Return!$B:$P,MATCH(G$2,[1]Burgiss_Return!$B$5:$P$5,0),0) -> -0.0334 | I14: =VLOOKUP($A14,[1]Burgiss_Return!$B:$P,MATCH(I$2,[1]Burgiss_Return!$B$5:$P$5,0),0) -> -0.0519 | J14: =VLOOKUP($A14,[1]Burgiss_Return!$B:$P,MATCH(J$2,[1]Burgiss_Return!$B$5:$P$5,0),0) -> -0.0926 | K14: -0.0062142281 | M14: =VLOOKUP($A14,[1]Burgiss_Return!$B:$P,MATCH(M$2,[1]Burgiss_Return!$B$5:$P$5,0),0) -> 0.0039 | Q14: -0.10073231
A15: 37621 | B15: =VLOOKUP($A15,[1]Burgiss_Return!$B:$P,MATCH(B$2,[1]Burgiss_Return!$B$5:$P$5,0),0) -> 0.0208 | C15: =VLOOKUP($A15,[1]Burgiss_Return!$B:$P,MATCH(C$2,[1]Burgiss_Return!$B$5:$P$5,0),0) -> -0.1076 | D15: =VLOOKUP($A15,[1]Burgiss_Return!$B:$P,MATCH(D$2,[1]Burgiss_Return!$B$5:$P$5,0),0) -> -0.1076 | E15: =VLOOKUP($A15,[1]Burgiss_Return!$B:$P,MATCH(E$2,[1]Burgiss_Return!$B$5:$P$5,0),0) -> -0.0336 | F15: =VLOOKUP($A15,[1]Burgiss_Return!$B:$P,MATCH(F$2,[1]Burgiss_Return!$B$5:$P$5,0),0) -> -0.0763 | G15: =VLOOKUP($A15,[1]Burgiss_Return!$B:$P,MATCH(G$2,[1]Burgiss_Return!$B$5:$P$5,0),0) -> -0.0336 | I15: =VLOOKUP($A15,[1]Burgiss_Return!$B:$P,MATCH(I$2,[1]Burgiss_Return!$B$5:$P$5,0),0) -> 0.0741 | J15: =VLOOKUP($A15,[1]Burgiss_Return!$B:$P,MATCH(J$2,[1]Burgiss_Return!$B$5:$P$5,0),0) -> 0.0067 | K15: 0.021797079 | M15: =VLOOKUP($A15,[1]Burgiss_Return!$B:$P,MATCH(M$2,[1]Burgiss_Return!$B$5:$P$5,0),0) -> -0.0077 | Q15: 0.029036769
A16: 37711 | B16: =VLOOKUP($A16,[1]Burgiss_Return!$B:$P,MATCH(B$2,[1]Burgiss_Return!$B$5:$P$5,0),0) -> 0.0042 | C16: =VLOOKUP($A16,[1]Burgiss_Return!$B:$P,MATCH(C$2,[1]Burgiss_Return!$B$5:$P$5,0),0) -> -0.0468 | D16: =VLOOKUP($A16,[1]Burgiss_Return!$B:$P,MATCH(D$2,[1]Burgiss_Return!$B$5:$P$5,0),0) -> -0.0468 | E16: =VLOOKUP($A16,[1]Burgiss_Return!$B:$P,MATCH(E$2,[1]Burgiss_Return!$B$5:$P$5,0),0) -> -0.0072 | F16: =VLOOKUP($A16,[1]Burgiss_Return!$B:$P,MATCH(F$2,[1]Burgiss_Return!$B$5:$P$5,0),0) -> -0.0315 | G16: =VLOOKUP($A16,[1]Burgiss_Return!$B:$P,MATCH(G$2,[1]Burgiss_Return!$B$5:$P$5,0),0) -> -0.0072 | I16: =VLOOKUP($A16,[1]Burgiss_Return!$B:$P,MATCH(I$2,[1]Burgiss_Return!$B$5:$P$5,0),0) -> 0.0151 | J16: =VLOOKUP($A16,[1]Burgiss_Return!$B:$P,MATCH(J$2,[1]Burgiss_Return!$B$5:$P$5,0),0) -> -0.0443 | K16: 0.021230963 | M16: =VLOOKUP($A16,[1]Burgiss_Return!$B:$P,MATCH(M$2,[1]Burgiss_Return!$B$5:$P$5,0),0) -> 0.0174 | Q16: -0.017310596
A17: 37802 | B17: =VLOOKUP($A17,[1]Burgiss_Return!$B:$P,MATCH(B$2,[1]Burgiss_Return!$B$5:$P$5,0),0) -> 0.0722 | C17: =VLOOKUP($A17,[1]Burgiss_Return!$B:$P,MATCH(C$2,[1]Burgiss_Return!$B$5:$P$5,0),0) -> -0.0103 | D17: =VLOOKUP($A17,[1]Burgiss_Return!$B:$P,MATCH(D$2,[1]Burgiss_Return!$B$5:$P$5,0),0) -> -0.0103 | E17: =VLOOKUP($A17,[1]Burgiss_Return!$B:$P,MATCH(E$2,[1]Burgiss_Return!$B$5:$P$5,0),0) -> 0.0222 | F17: =VLOOKUP($A17,[1]Burgiss_Return!$B:$P,MATCH(F$2,[1]Burgiss_Return!$B$5:$P$5,0),0) -> 0.0201 | G17: =VLOOKUP($A17,[1]Burgiss_Return!$B:$P,MATCH(G$2,[1]Burgiss_Return!$B$5:$P$5,0),0) -> 0.0222 | I17: =VLOOKUP($A17,[1]Burgiss_Return!$B:$P,MATCH(I$2,[1]Burgiss_Return!$B$5:$P$5,0),0) -> 0.1353 | J17: =VLOOKUP($A17,[1]Burgiss_Return!$B:$P,MATCH(J$2,[1]Burgiss_Return!$B$5:$P$5,0),0) -> 0.0623 | K17: 0.028255806 | M17: =VLOOKUP($A17,[1]Burgiss_Return!$B:$P,MATCH(M$2,[1]Burgiss_Return!$B$5:$P$5,0),0) -> 0.0134 | Q17: 0.14436782
A18: 37894 | B18: =VLOOKUP($A18,[1]Burgiss_Return!$B:$P,MATCH(B$2,[1]Burgiss_Return!$B$5:$P$5,0),0) -> 0.0434 | C18: =VLOOKUP($A18,[1]Burgiss_Return!$B:$P,MATCH(C$2,[1]Burgiss_Return!$B$5:$P$5,0),0) -> -0.0305 | D18: =VLOOKUP($A18,[1]Burgiss_Return!$B:$P,MATCH(D$2,[1]Burgiss_Return!$B$5:$P$5,0),0) -> -0.0305 | E18: =VLOOKUP($A18,[1]Burgiss_Return!$B:$P,MATCH(E$2,[1]Burgiss_Return!$B$5:$P$5,0),0) -> 0.0398 | F18: =VLOOKUP($A18,[1]Burgiss_Return!$B:$P,MATCH(F$2,[1]Burgiss_Return!$B$5:$P$5,0),0) -> 0.0027 | G18: =VLOOKUP($A18,[1]Burgiss_Return!$B:$P,MATCH(G$2,[1]Burgiss_Return!$B$5:$P$5,0),0) -> 0.0398 | I18: =VLOOKUP($A18,[1]Burgiss_Return!$B:$P,MATCH(I$2,[1]Burgiss_Return!$B$5:$P$5,0),0) -> 0.0588 | J18: =VLOOKUP($A18,[1]Burgiss_Return!$B:$P,MATCH(J$2,[1]Burgiss_Return!$B$5:$P$5,0),0) -> 0.1035 | K18: 0.011475977 | M18: =VLOOKUP($A18,[1]Burgiss_Return!$B:$P,MATCH(M$2,[1]Burgiss_Return!$B$5:$P$5,0),0) -> 0.0165 | Q18: 0.11854139
A19: 37986 | B19: =VLOOKUP($A19,[1]Burgiss_Return!$B:$P,MATCH(B$2,[1]Burgiss_Return!$B$5:$P$5,0),0) -> 0.126 | C19: =VLOOKUP($A19,[1]Burgiss_Return!$B:$P,MATCH(C$2,[1]Burgiss_Return!$B$5:$P$5,0),0) -> 0.0167 | D19: =VLOOKUP($A19,[1]Burgiss_Return!$B:$P,MATCH(D$2,[1]Burgiss_Return!$B$5:$P$5,0),0) -> 0.0167 | E19: =VLOOKUP($A19,[1]Burgiss_Return!$B:$P,MATCH(E$2,[1]Burgiss_Return!$B$5:$P$5,0),0) -> 0.1883 | F19: =VLOOKUP($A19,[1]Burgiss_Return!$B:$P,MATCH(F$2,[1]Burgiss_Return!$B$5:$P$5,0),0) -> 0.0826 | G19: =VLOOKUP($A19,[1]Burgiss_Return!$B:$P,MATCH(G$2,[1]Burgiss_Return!$B$5:$P$5,0),0) -> 0.1883 | I19: =VLOOKUP($A19,[1]Burgiss_Return!$B:$P,MATCH(I$2,[1]Burgiss_Return!$B$5:$P$5,0),0) -> 0.0755 | J19: =VLOOKUP($A19,[1]Burgiss_Return!$B:$P,MATCH(J$2,[1]Burgiss_Return!$B$5:$P$5,0),0) -> 0.1521 | K19: 0.026332629 | M19: =VLOOKUP($A19,[1]Burgiss_Return!$B:$P,MATCH(M$2,[1]Burgiss_Return!$B$5:$P$5,0),0) -> 0.057 | Q19: 0.11851888
A20: 38077 | B20: =VLOOKUP($A20,[1]Burgiss_Return!$B:$P,MATCH(B$2,[1]Burgiss_Return!$B$5:$P$5,0),0) -> 0.0159 | C20: =VLOOKUP($A20,[1]Burgiss_Return!$B:$P,MATCH(C$2,[1]Burgiss_Return!$B$5:$P$5,0),0) -> 0.0152 | D20: =VLOOKUP($A20,[1]Burgiss_Return!$B:$P,MATCH(D$2,[1]Burgiss_Return!$B$5:$P$5,0),0) -> 0.0152 | E20: =VLOOKUP($A20,[1]Burgiss_Return!$B:$P,MATCH(E$2,[1]Burgiss_Return!$B$5:$P$5,0),0) -> 0.0362 | F20: =VLOOKUP($A20,[1]Burgiss_Return!$B:$P,MATCH(F$2,[1]Burgiss_Return!$B$5:$P$5,0),0) -> -0.0121 | G20: =VLOOKUP($A20,[1]Burgiss_Return!$B:$P,MATCH(G$2,[1]Burgiss_Return!$B$5:$P$5,0),0) -> 0.0362 | I20: =VLOOKUP($A20,[1]Burgiss_Return!$B:$P,MATCH(I$2,[1]Burgiss_Return!$B$5:$P$5,0),0) -> 0.0351 | J20: =VLOOKUP($A20,[1]Burgiss_Return!$B:$P,MATCH(J$2,[1]Burgiss_Return!$B$5:$P$5,0),0) -> 0.1377 | K20: 0.023805916 | M20: =VLOOKUP($A20,[1]Burgiss_Return!$B:$P,MATCH(M$2,[1]Burgiss_Return!$B$5:$P$5,0),0) -> 0.0184 | Q20: 0.13489849
A21: 38168 | B21: =VLOOKUP($A21,[1]Burgiss_Return!$B:$P,MATCH(B$2,[1]Burgiss_Return!$B$5:$P$5,0),0) -> 0.0519 | C21: =VLOOKUP($A21,[1]Burgiss_Return!$B:$P,MATCH(C$2,[1]Burgiss_Return!$B$5:$P$5,0),0) -> 0.003 | D21: =VLOOKUP($A21,[1]Burgiss_Return!$B:$P,MATCH(D$2,[1]Burgiss_Return!$B$5:$P$5,0),0) -> 0.003 | E21: =VLOOKUP($A21,[1]Burgiss_Return!$B:$P,MATCH(E$2,[1]Burgiss_Return!$B$5:$P$5,0),0) -> 0.0483 | F21: =VLOOKUP($A21,[1]Burgiss_Return!$B:$P,MATCH(F$2,[1]Burgiss_Return!$B$5:$P$5,0),0) -> 0.0245 | G21: =VLOOKUP($A21,[1]Burgiss_Return!$B:$P,MATCH(G$2,[1]Burgiss_Return!$B$5:$P$5,0),0) -> 0.0483 | I21: =VLOOKUP($A21,[1]Burgiss_Return!$B:$P,MATCH(I$2,[1]Burgiss_Return!$B$5:$P$5,0),0) -> 0.0313 | J21: =VLOOKUP($A21,[1]Burgiss_Return!$B:$P,MATCH(J$2,[1]Burgiss_Return!$B$5:$P$5,0),0) -> 0.0265 | K21: -0.0065285202 | M21: =VLOOKUP($A21,[1]Burgiss_Return!$B:$P,MATCH(M$2,[1]Burgiss_Return!$B$5:$P$5,0),0) -> 0.0296 | Q21: -0.041273355
A22: 38260 | B22: =VLOOKUP($A22,[1]Burgiss_Return!$B:$P,MATCH(B$2,[1]Burgiss_Return!$B$5:$P$5,0),0) -> 0.0237 | C22: =VLOOKUP($A22,[1]Burgiss_Return!$B:$P,MATCH(C$2,[1]Burgiss_Return!$B$5:$P$5,0),0) -> 0.0653 | D22: =VLOOKUP($A22,[1]Burgiss_Return!$B:$P,MATCH(D$2,[1]Burgiss_Return!$B$5:$P$5,0),0) -> 0.0653 | E22: =VLOOKUP($A22,[1]Burgiss_Return!$B:$P,MATCH(E$2,[1]Burgiss_Return!$B$5:$P$5,0),0) -> 0.0474 | F22: =VLOOKUP($A22,[1]Burgiss_Return!$B:$P,MATCH(F$2,[1]Burgiss_Return!$B$5:$P$5,0),0) -> 0.0242 | G22: =VLOOKUP($A22,[1]Burgiss_Return!$B:$P,MATCH(G$2,[1]Burgiss_Return!$B$5:$P$5,0),0) -> 0.0474 | I22: =VLOOKUP($A22,[1]Burgiss_Return!$B:$P,MATCH(I$2,[1]Burgiss_Return!$B$5:$P$5,0),0) -> 0.0452 | J22: =VLOOKUP($A22,[1]Burgiss_Return!$B:$P,MATCH(J$2,[1]Burgiss_Return!$B$5:$P$5,0),0) -> 0.0377 | K22: 0.0047303679 | M22: =VLOOKUP($A22,[1]Burgiss_Return!$B:$P,MATCH(M$2,[1]Burgiss_Return!$B$5:$P$5,0),0) -> 0.0038 | Q22: 0.07574395
A23: 38352 | B23: =VLOOKUP($A23,[1]Burgiss_Return!$B:$P,MATCH(B$2,[1]Burgiss_Return!$B$5:$P$5,0),0) -> 0.1543 | C23: =VLOOKUP($A23,[1]Burgiss_Return!$B:$P,MATCH(C$2,[1]Burgiss_Return!$B$5:$P$5,0),0) -> 0.0597 | D23: =VLOOKUP($A23,[1]Burgiss_Return!$B:$P,MATCH(D$2,[1]Burgiss_Return!$B$5:$P$5,0),0) -> 0.0597 | E23: =VLOOKUP($A23,[1]Burgiss_Return!$B:$P,MATCH(E$2,[1]Burgiss_Return!$B$5:$P$5,0),0) -> 0.1506 | F23: =VLOOKUP($A23,[1]Burgiss_Return!$B:$P,MATCH(F$2,[1]Burgiss_Return!$B$5:$P$5,0),0) -> 0.0959 | G23: =VLOOKUP($A23,[1]Burgiss_Return!$B:$P,MATCH(G$2,[1]Burgiss_Return!$B$5:$P$5,0),0) -> 0.1506 | I23: =VLOOKUP($A23,[1]Burgiss_Return!$B:$P,MATCH(I$2,[1]Burgiss_Return!$B$5:$P$5,0),0) -> 0.101 | J23: =VLOOKUP($A23,[1]Burgiss_Return!$B:$P,MATCH(J$2,[1]Burgiss_Return!$B$5:$P$5,0),0) -> 0.1219 | K23: 0.035564989 | M23: =VLOOKUP($A23,[1]Burgiss_Return!$B:$P,MATCH(M$2,[1]Burgiss_Return!$B$5:$P$5,0),0) -> 0.1702 | Q23: 0.17869933
... A30: 38990 | B30: =VLOOKUP($A30,[1]Burgiss_Return!$B:$P,MATCH(B$2,[1]Burgiss_Return!$B$5:$P$5,0),0) -> 0.0321 | C30: =VLOOKUP($A30,[1]Burgiss_Return!$B:$P,MATCH(C$2,[1]Burgiss_Return!$B$5:$P$5,0),0) -> 0.0145 | D30: =VLOOKUP($A30,[1]Burgiss_Return!$B:$P,MATCH(D$2,[1]Burgiss_Return!$B$5:$P$5,0),0) -> 0.0145 | E30: =VLOOKUP($A30,[1]Burgiss_Return!$B:$P,MATCH(E$2,[1]Burgiss_Return!$B$5:$P$5,0),0) -> 0.0394 | F30: =VLOOKUP($A30,[1]Burgiss_Return!$B:$P,MATCH(F$2,[1]Burgiss_Return!$B$5:$P$5,0),0) -> 0.0286 | G30: =VLOOKUP($A30,[1]Burgiss_Return!$B:$P,MATCH(G$2,[1]Burgiss_Return!$B$5:$P$5,0),0) -> 0.0394 | I30: =VLOOKUP($A30,[1]Burgiss_Return!$B:$P,MATCH(I$2,[1]Burgiss_Return!$B$5:$P$5,0),0) -> 0.0283 | J30: =VLOOKUP($A30,[1]Burgiss_Return!$B:$P,MATCH(J$2,[1]Burgiss_Return!$B$5:$P$5,0),0) -> -0.0008 | K30: 0.0046450011 | M30: =VLOOKUP($A30,[1]Burgiss_Return!$B:$P,MATCH(M$2,[1]Burgiss_Return!$B$5:$P$5,0),0) -> 0.0343 | Q30: 0.09918614
A31: 39082 | B31: =VLOOKUP($A31,[1]Burgiss_Return!$B:$P,MATCH(B$2,[1]Burgiss_Return!$B$5:$P$5,0),0) -> 0.1756 | C31: =VLOOKUP($A31,[1]Burgiss_Return!$B:$P,MATCH(C$2,[1]Burgiss_Return!$B$5:$P$5,0),0) -> 0.0914 | D31: =VLOOKUP($A31,[1]Burgiss_Return!$B:$P,MATCH(D$2,[1]Burgiss_Return!$B$5:$P$5,0),0) -> 0.0914 | E31: =VLOOKUP($A31,[1]Burgiss_Return!$B:$P,MATCH(E$2,[1]Burgiss_Return!$B$5:$P$5,0),0) -> 0.1077 | F31: =VLOOKUP($A31,[1]Burgiss_Return!$B:$P,MATCH(F$2,[1]Burgiss_Return!$B$5:$P$5,0),0) -> 0.0696 | G31: =VLOOKUP($A31,[1]Burgiss_Return!$B:$P,MATCH(G$2,[1]Burgiss_Return!$B$5:$P$5,0),0) -> 0.1077 | I31: =VLOOKUP($A31,[1]Burgiss_Return!$B:$P,MATCH(I$2,[1]Burgiss_Return!$B$5:$P$5,0),0) -> 0.0764 | J31: =VLOOKUP($A31,[1]Burgiss_Return!$B:$P,MATCH(J$2,[1]Burgiss_Return!$B$5:$P$5,0),0) -> 0.1133 | K31: 0.039354702 | M31: =VLOOKUP($A31,[1]Burgiss_Return!$B:$P,MATCH(M$2,[1]Burgiss_Return!$B$5:$P$5,0),0) -> 0.1758 | Q31: 0.14040027 | R31: =VLOOKUP($A31,[1]Burgiss_Return!$B:$P,MATCH(R$2,[1]Burgiss_Return!$B$5:$P$5,0),0) -> -0.0407 | S31: =VLOOKUP($A31,[1]Burgiss_Return!$B:$P,MATCH(S$2,[1]Burgiss_Return!$B$5:$P$5,0),0) -> -0.0407 | T31: =VLOOKUP($A31,[1]Burgiss_Return!$B:$P,MATCH(T$2,[1]Burgiss_Return!$B$5:$P$5,0),0) -> -0.0407 | U31: =VLOOKUP($A31,[1]Burgiss_Return!$B:$P,MATCH(U$2,[1]Burgiss_Return!$B$5:$P$5,0),0) -> -0.0407
A32: 39172 | B32: =VLOOKUP($A32,[1]Burgiss_Return!$B:$P,MATCH(B$2,[1]Burgiss_Return!$B$5:$P$5,0),0) -> 0.0543 | C32: =VLOOKUP($A32,[1]Burgiss_Return!$B:$P,MATCH(C$2,[1]Burgiss_Return!$B$5:$P$5,0),0) -> 0.0115 | D32: =VLOOKUP($A32,[1]Burgiss_Return!$B:$P,MATCH(D$2,[1]Burgiss_Return!$B$5:$P$5,0),0) -> 0.0115 | E32: =VLOOKUP($A32,[1]Burgiss_Return!$B:$P,MATCH(E$2,[1]Burgiss_Return!$B$5:$P$5,0),0) -> 0.0364 | F32: =VLOOKUP($A32,[1]Burgiss_Return!$B:$P,MATCH(F$2,[1]Burgiss_Return!$B$5:$P$5,0),0) -> 0.042 | G32: =VLOOKUP($A32,[1]Burgiss_Return!$B:$P,MATCH(G$2,[1]Burgiss_Return!$B$5:$P$5,0),0) -> 0.0364 | I32: =VLOOKUP($A32,[1]Burgiss_Return!$B:$P,MATCH(I$2,[1]Burgiss_Return!$B$5:$P$5,0),0) -> 0.0474 | J32: =VLOOKUP($A32,[1]Burgiss_Return!$B:$P,MATCH(J$2,[1]Burgiss_Return!$B$5:$P$5,0),0) -> 0.0411 | K32: 0.031239626 | M32: =VLOOKUP($A32,[1]Burgiss_Return!$B:$P,MATCH(M$2,[1]Burgiss_Return!$B$5:$P$5,0),0) -> 0.1033 | Q32: 0.062226222 | R32: =VLOOKUP($A32,[1]Burgiss_Return!$B:$P,MATCH(R$2,[1]Burgiss_Return!$B$5:$P$5,0),0) -> 0.0054 | S32: =VLOOKUP($A32,[1]Burgiss_Return!$B:$P,MATCH(S$2,[1]Burgiss_Return!$B$5:$P$5,0),0) -> 0.0054 | T32: =VLOOKUP($A32,[1]Burgiss_Return!$B:$P,MATCH(T$2,[1]Burgiss_Return!$B$5:$P$5,0),0) -> 0.0054 | U32: =VLOOKUP($A32,[1]Burgiss_Return!$B:$P,MATCH(U$2,[1]Burgiss_Return!$B$5:$P$5,0),0) -> 0.0054
A33: 39263 | B33: =VLOOKUP($A33,[1]Burgiss_Return!$B:$P,MATCH(B$2,[1]Burgiss_Return!$B$5:$P$5,0),0) -> 0.1117 | C33: =VLOOKUP($A33,[1]Burgiss_Return!$B:$P,MATCH(C$2,[1]Burgiss_Return!$B$5:$P$5,0),0) -> 0.0789 | D33: =VLOOKUP($A33,[1]Burgiss_Return!$B:$P,MATCH(D$2,[1]Burgiss_Return!$B$5:$P$5,0),0) -> 0.0789 | E33: =VLOOKUP($A33,[1]Burgiss_Return!$B:$P,MATCH(E$2,[1]Burgiss_Return!$B$5:$P$5,0),0) -> 0.0672 | F33: =VLOOKUP($A33,[1]Burgiss_Return!$B:$P,MATCH(F$2,[1]Burgiss_Return!$B$5:$P$5,0),0) -> 0.0641 | G33: =VLOOKUP($A33,[1]Burgiss_Return!$B:$P,MATCH(G$2,[1]Burgiss_Return!$B$5:$P$5,0),0) -> 0.0672 | I33: =VLOOKUP($A33,[1]Burgiss_Return!$B:$P,MATCH(I$2,[1]Burgiss_Return!$B$5:$P$5,0),0) -> 0.0586 | J33: =VLOOKUP($A33,[1]Burgiss_Return!$B:$P,MATCH(J$2,[1]Burgiss_Return!$B$5:$P$5,0),0) -> 0.1631 | K33: 0.032940973 | M33: =VLOOKUP($A33,[1]Burgiss_Return!$B:$P,MATCH(M$2,[1]Burgiss_Return!$B$5:$P$5,0),0) -> 0.0523 | Q33: -0.058512745 | R33: =VLOOKUP($A33,[1]Burgiss_Return!$B:$P,MATCH(R$2,[1]Burgiss_Return!$B$5:$P$5,0),0) -> 0.0344 | S33: =VLOOKUP($A33,[1]Burgiss_Return!$B:$P,MATCH(S$2,[1]Burgiss_Return!$B$5:$P$5,0),0) -> 0.0344 | T33: =VLOOKUP($A33,[1]Burgiss_Return!$B:$P,MATCH(T$2,[1]Burgiss_Return!$B$5:$P$5,0),0) -> 0.0344 | U33: =VLOOKUP($A33,[1]Burgiss_Return!$B:$P,MATCH(U$2,[1]Burgiss_Return!$B$5:$P$5,0),0) -> 0.0344
A34: 39355 | B34: =VLOOKUP($A34,[1]Burgiss_Return!$B:$P,MATCH(B$2,[1]Burgiss_Return!$B$5:$P$5,0),0) -> 0.0283 | C34: =VLOOKUP($A34,[1]Burgiss_Return!$B:$P,MATCH(C$2,[1]Burgiss_Return!$B$5:$P$5,0),0) -> 0.0236 | D34: =VLOOKUP($A34,[1]Burgiss_Return!$B:$P,MATCH(D$2,[1]Burgiss_Return!$B$5:$P$5,0),0) -> 0.0236 | E34: =VLOOKUP($A34,[1]Burgiss_Return!$B:$P,MATCH(E$2,[1]Burgiss_Return!$B$5:$P$5,0),0) -> 0.0795 | F34: =VLOOKUP($A34,[1]Burgiss_Return!$B:$P,MATCH(F$2,[1]Burgiss_Return!$B$5:$P$5,0),0) -> 0.0499 | G34: =VLOOKUP($A34,[1]Burgiss_Return!$B:$P,MATCH(G$2,[1]Burgiss_Return!$B$5:$P$5,0),0) -> 0.0795 | I34: =VLOOKUP($A34,[1]Burgiss_Return!$B:$P,MATCH(I$2,[1]Burgiss_Return!$B$5:$P$5,0),0) -> -0.0083 | J34: =VLOOKUP($A34,[1]Burgiss_Return!$B:$P,MATCH(J$2,[1]Burgiss_Return!$B$5:$P$5,0),0) -> 0.0799 | K34: -0.0044834015 | M34: =VLOOKUP($A34,[1]Burgiss_Return!$B:$P,MATCH(M$2,[1]Burgiss_Return!$B$5:$P$5,0),0) -> -0.0012 | Q34: 0.036556755 | R34: =VLOOKUP($A34,[1]Burgiss_Return!$B:$P,MATCH(R$2,[1]Burgiss_Return!$B$5:$P$5,0),0) -> 0.0002 | S34: =VLOOKUP($A34,[1]Burgiss_Return!$B:$P,MATCH(S$2,[1]Burgiss_Return!$B$5:$P$5,0),0) -> 0.0002 | T34: =VLOOKUP($A34,[1]Burgiss_Return!$B:$P,MATCH(T$2,[1]Burgiss_Return!$B$5:$P$5,0),0) -> 0.0002 | U34: =VLOOKUP($A34,[1]Burgiss_Return!$B:$P,MATCH(U$2,[1]Burgiss_Return!$B$5:$P$5,0),0) -> 0.0002
A35: 39447 | B35: =VLOOKUP($A35,[1]Burgiss_Return!$B:$P,MATCH(B$2,[1]Burgiss_Return!$B$5:$P$5,0),0) -> 0.0369 | C35: =VLOOKUP($A35,[1]Burgiss_Return!$B:$P,MATCH(C$2,[1]Burgiss_Return!$B$5:$P$5,0),0) -> 0.0386 | D35: =VLOOKUP($A35,[1]Burgiss_Return!$B:$P,MATCH(D$2,[1]Burgiss_Return!$B$5:$P$5,0),0) -> 0.0386 | E35: =VLOOKUP($A35,[1]Burgiss_Return!$B:$P,MATCH(E$2,[1]Burgiss_Return!$B$5:$P$5,0),0) -> 0.0523 | F35: =VLOOKUP($A35,[1]Burgiss_Return!$B:$P,MATCH(F$2,[1]Burgiss_Return!$B$5:$P$5,0),0) -> 0.0562 | G35: =VLOOKUP($A35,[1]Burgiss_Return!$B:$P,MATCH(G$2,[1]Burgiss_Return!$B$5:$P$5,0),0) -> 0.0523 | I35: =VLOOKUP($A35,[1]Burgiss_Return!$B:$P,MATCH(I$2,[1]Burgiss_Return!$B$5:$P$5,0),0) -> -0.0351 | J35: =VLOOKUP($A35,[1]Burgiss_Return!$B:$P,MATCH(J$2,[1]Burgiss_Return!$B$5:$P$5,0),0) -> 0.1033 | K35: 0.015416412 | M35: =VLOOKUP($A35,[1]Burgiss_Return!$B:$P,MATCH(M$2,[1]Burgiss_Return!$B$5:$P$5,0),0) -> 0.0075 | Q35: -0.10245851 | R35: =VLOOKUP($A35,[1]Burgiss_Return!$B:$P,MATCH(R$2,[1]Burgiss_Return!$B$5:$P$5,0),0) -> 0.0967 | S35: =VLOOKUP($A35,[1]Burgiss_Return!$B:$P,MATCH(S$2,[1]Burgiss_Return!$B$5:$P$5,0),0) -> 0.0967 | T35: =VLOOKUP($A35,[1]Burgiss_Return!$B:$P,MATCH(T$2,[1]Burgiss_Return!$B$5:$P$5,0),0) -> 0.0967 | U35: =VLOOKUP($A35,[1]Burgiss_Return!$B:$P,MATCH(U$2,[1]Burgiss_Return!$B$5:$P$5,0),0) -> 0.0967
A36: 39538 | B36: =VLOOKUP($A36,[1]Burgiss_Return!$B:$P,MATCH(B$2,[1]Burgiss_Return!$B$5:$P$5,0),0) -> 0.0035 | C36: =VLOOKUP($A36,[1]Burgiss_Return!$B:$P,MATCH(C$2,[1]Burgiss_Return!$B$5:$P$5,0),0) -> -0.0136 | D36: =VLOOKUP($A36,[1]Burgiss_Return!$B:$P,MATCH(D$2,[1]Burgiss_Return!$B$5:$P$5,0),0) -> -0.0136 | E36: =VLOOKUP($A36,[1]Burgiss_Return!$B:$P,MATCH(E$2,[1]Burgiss_Return!$B$5:$P$5,0),0) -> 0.0117 | F36: =VLOOKUP($A36,[1]Burgiss_Return!$B:$P,MATCH(F$2,[1]Burgiss_Return!$B$5:$P$5,0),0) -> 0.0071 | G36: =VLOOKUP($A36,[1]Burgiss_Return!$B:$P,MATCH(G$2,[1]Burgiss_Return!$B$5:$P$5,0),0) -> 0.0117 | I36: =VLOOKUP($A36,[1]Burgiss_Return!$B:$P,MATCH(I$2,[1]Burgiss_Return!$B$5:$P$5,0),0) -> -0.0373 | J36: =VLOOKUP($A36,[1]Burgiss_Return!$B:$P,MATCH(J$2,[1]Burgiss_Return!$B$5:$P$5,0),0) -> -0.0756 | K36: -0.028564399 | L36: 0.013174 | M36: =VLOOKUP($A36,[1]Burgiss_Return!$B:$P,MATCH(M$2,[1]Burgiss_Return!$B$5:$P$5,0),0) -> 0.0143 | N36: 0.013174 | Q36: -0.05629264 | R36: =VLOOKUP($A36,[1]Burgiss_Return!$B:$P,MATCH(R$2,[1]Burgiss_Return!$B$5:$P$5,0),0) -> 0.0354 | S36: =VLOOKUP($A36,[1]Burgiss_Return!$B:$P,MATCH(S$2,[1]Burgiss_Return!$B$5:$P$5,0),0) -> 0.0354 | T36: =VLOOKUP($A36,[1]Burgiss_Return!$B:$P,MATCH(T$2,[1]Burgiss_Return!$B$5:$P$5,0),0) -> 0.0354 | U36: =VLOOKUP($A36,[1]Burgiss_Return!$B:$P,MATCH(U$2,[1]Burgiss_Return!$B$5:$P$5,0),0) -> 0.0354
A37: 39629 | B37: =VLOOKUP($A37,[1]Burgiss_Return!$B:$P,MATCH(B$2,[1]Burgiss_Return!$B$5:$P$5,0),0) -> -0.0159 | C37: =VLOOKUP($A37,[1]Burgiss_Return!$B:$P,MATCH(C$2,[1]Burgiss_Return!$B$5:$P$5,0),0) -> -0.0057 | D37: =VLOOKUP($A37,[1]Burgiss_Return!$B:$P,MATCH(D$2,[1]Burgiss_Return!$B$5:$P$5,0),0) -> -0.0057 | E37: =VLOOKUP($A37,[1]Burgiss_Return!$B:$P,MATCH(E$2,[1]Burgiss_Return!$B$5:$P$5,0),0) -> -0.0065 | F37: =VLOOKUP($A37,[1]Burgiss_Return!$B:$P,MATCH(F$2,[1]Burgiss_Return!$B$5:$P$5,0),0) -> -0.0083 | G37: =VLOOKUP($A37,[1]Burgiss_Return!$B:$P,MATCH(G$2,[1]Burgiss_Return!$B$5:$P$5,0),0) -> -0.0065 | I37: =VLOOKUP($A37,[1]Burgiss_Return!$B:$P,MATCH(I$2,[1]Burgiss_Return!$B$5:$P$5,0),0) -> 0.0435 | J37: =VLOOKUP($A37,[1]Burgiss_Return!$B:$P,MATCH(J$2,[1]Burgiss_Return!$B$5:$P$5,0),0) -> -0.0411 | K37: 0.016810447 | L37: 0.00666 | M37: =VLOOKUP($A37,[1]Burgiss_Return!$B:$P,MATCH(M$2,[1]Burgiss_Return!$B$5:$P$5,0),0) -> -0.0239 | N37: 0.00666 | Q37: -0.085597679 | R37: =VLOOKUP($A37,[1]Burgiss_Return!$B:$P,MATCH(R$2,[1]Burgiss_Return!$B$5:$P$5,0),0) -> 0.0308 | S37: =VLOOKUP($A37,[1]Burgiss_Return!$B:$P,MATCH(S$2,[1]Burgiss_Return!$B$5:$P$5,0),0) -> 0.0308 | T37: =VLOOKUP($A37,[1]Burgiss_Return!$B:$P,MATCH(T$2,[1]Burgiss_Return!$B$5:$P$5,0),0) -> 0.0308 | U37: =VLOOKUP($A37,[1]Burgiss_Return!$B:$P,MATCH(U$2,[1]Burgiss_Return!$B$5:$P$5,0),0) -> 0.0308
A38: 39721 | B38: =VLOOKUP($A38,[1]Burgiss_Return!$B:$P,MATCH(B$2,[1]Burgiss_Return!$B$5:$P$5,0),0) -> -0.1017 | C38: =VLOOKUP($A38,[1]Burgiss_Return!$B:$P,MATCH(C$2,[1]Burgiss_Return!$B$5:$P$5,0),0) -> -0.03 | D38: =VLOOKUP($A38,[1]Burgiss_Return!$B:$P,MATCH(D$2,[1]Burgiss_Return!$B$5:$P$5,0),0) -> -0.03 | E38: =VLOOKUP($A38,[1]Burgiss_Return!$B:$P,MATCH(E$2,[1]Burgiss_Return!$B$5:$P$5,0),0) -> -0.0339 | F38: =VLOOKUP($A38,[1]Burgiss_Return!$B:$P,MATCH(F$2,[1]Burgiss_Return!$B$5:$P$5,0),0) -> -0.0703 | G38: =VLOOKUP($A38,[1]Burgiss_Return!$B:$P,MATCH(G$2,[1]Burgiss_Return!$B$5:$P$5,0),0) -> -0.0339 | I38: =VLOOKUP($A38,[1]Burgiss_Return!$B:$P,MATCH(I$2,[1]Burgiss_Return!$B$5:$P$5,0),0) -> -0.1325 | J38: =VLOOKUP($A38,[1]Burgiss_Return!$B:$P,MATCH(J$2,[1]Burgiss_Return!$B$5:$P$5,0),0) -> -0.0909 | K38: -0.083556744 | L38: -0.079068 | M38: =VLOOKUP($A38,[1]Burgiss_Return!$B:$P,MATCH(M$2,[1]Burgiss_Return!$B$5:$P$5,0),0) -> -0.0995 | N38: -0.079068 | Q38: -0.10410579 | R38: =VLOOKUP($A38,[1]Burgiss_Return!$B:$P,MATCH(R$2,[1]Burgiss_Return!$B$5:$P$5,0),0) -> -0.0922 | S38: =VLOOKUP($A38,[1]Burgiss_Return!$B:$P,MATCH(S$2,[1]Burgiss_Return!$B$5:$P$5,0),0) -> -0.0922 | T38: =VLOOKUP($A38,[1]Burgiss_Return!$B:$P,MATCH(T$2,[1]Burgiss_Return!$B$5:$P$5,0),0) -> -0.0922 | U38: =VLOOKUP($A38,[1]Burgiss_Return!$B:$P,MATCH(U$2,[1]Burgiss_Return!$B$5:$P$5,0),0) -> -0.0922
A39: 39813 | B39: =VLOOKUP($A39,[1]Burgiss_Return!$B:$P,MATCH(B$2,[1]Burgiss_Return!$B$5:$P$5,0),0) -> -0.1887 | C39: =VLOOKUP($A39,[1]Burgiss_Return!$B:$P,MATCH(C$2,[1]Burgiss_Return!$B$5:$P$5,0),0) -> -0.1139 | D39: =VLOOKUP($A39,[1]Burgiss_Return!$B:$P,MATCH(D$2,[1]Burgiss_Return!$B$5:$P$5,0),0) -> -0.1139 | E39: =VLOOKUP($A39,[1]Burgiss_Return!$B:$P,MATCH(E$2,[1]Burgiss_Return!$B$5:$P$5,0),0) -> -0.161 | F39: =VLOOKUP($A39,[1]Burgiss_Return!$B:$P,MATCH(F$2,[1]Burgiss_Return!$B$5:$P$5,0),0) -> -0.1435 | G39: =VLOOKUP($A39,[1]Burgiss_Return!$B:$P,MATCH(G$2,[1]Burgiss_Return!$B$5:$P$5,0),0) -> -0.161 | I39: =VLOOKUP($A39,[1]Burgiss_Return!$B:$P,MATCH(I$2,[1]Burgiss_Return!$B$5:$P$5,0),0) -> -0.1982 | J39: =VLOOKUP($A39,[1]Burgiss_Return!$B:$P,MATCH(J$2,[1]Burgiss_Return!$B$5:$P$5,0),0) -> -0.1738 | K39: -0.11474976 | L39: -0.154965 | M39: =VLOOKUP($A39,[1]Burgiss_Return!$B:$P,MATCH(M$2,[1]Burgiss_Return!$B$5:$P$5,0),0) -> -0.269 | N39: -0.154965 | Q39: -0.32378532 | R39: =VLOOKUP($A39,[1]Burgiss_Return!$B:$P,MATCH(R$2,[1]Burgiss_Return!$B$5:$P$5,0),0) -> -0.1083 | S39: =VLOOKUP($A39,[1]Burgiss_Return!$B:$P,MATCH(S$2,[1]Burgiss_Return!$B$5:$P$5,0),0) -> -0.1083 | T39: =VLOOKUP($A39,[1]Burgiss_Return!$B:$P,MATCH(T$2,[1]Burgiss_Return!$B$5:$P$5,0),0) -> -0.1083 | U39: =VLOOKUP($A39,[1]Burgiss_Return!$B:$P,MATCH(U$2,[1]Burgiss_Return!$B$5:$P$5,0),0) -> -0.1083
A40: 39903 | B40: =VLOOKUP($A40,[1]Burgiss_Return!$B:$P,MATCH(B$2,[1]Burgiss_Return!$B$5:$P$5,0),0) -> -0.0477 | C40: =VLOOKUP($A40,[1]Burgiss_Return!$B:$P,MATCH(C$2,[1]Burgiss_Return!$B$5:$P$5,0),0) -> -0.0253 | D40: =VLOOKUP($A40,[1]Burgiss_Return!$B:$P,MATCH(D$2,[1]Burgiss_Return!$B$5:$P$5,0),0) -> -0.0253 | E40: =VLOOKUP($A40,[1]Burgiss_Return!$B:$P,MATCH(E$2,[1]Burgiss_Return!$B$5:$P$5,0),0) -> -0.0282 | F40: =VLOOKUP($A40,[1]Burgiss_Return!$B:$P,MATCH(F$2,[1]Burgiss_Return!$B$5:$P$5,0),0) -> -0.0421 | G40: =VLOOKUP($A40,[1]Burgiss_Return!$B:$P,MATCH(G$2,[1]Burgiss_Return!$B$5:$P$5,0),0) -> -0.0282 | I40: =VLOOKUP($A40,[1]Burgiss_Return!$B:$P,MATCH(I$2,[1]Burgiss_Return!$B$5:$P$5,0),0) -> -0.0426 | J40: =VLOOKUP($A40,[1]Burgiss_Return!$B:$P,MATCH(J$2,[1]Burgiss_Return!$B$5:$P$5,0),0) -> -0.0038 | K40: 0.007082346 | L40: -0.111865 | M40: =VLOOKUP($A40,[1]Burgiss_Return!$B:$P,MATCH(M$2,[1]Burgiss_Return!$B$5:$P$5,0),0) -> -0.1156 | N40: -0.111865 | Q40: -0.22094595 | R40: =VLOOKUP($A40,[1]Burgiss_Return!$B:$P,MATCH(R$2,[1]Burgiss_Return!$B$5:$P$5,0),0) -> -0.0706 | S40: =VLOOKUP($A40,[1]Burgiss_Return!$B:$P,MATCH(S$2,[1]Burgiss_Return!$B$5:$P$5,0),0) -> -0.0706 | T40: =VLOOKUP($A40,[1]Burgiss_Return!$B:$P,MATCH(T$2,[1]Burgiss_Return!$B$5:$P$5,0),0) -> -0.0706 | U40: =VLOOKUP($A40,[1]Burgiss_Return!$B:$P,MATCH(U$2,[1]Burgiss_Return!$B$5:$P$5,0),0) -> -0.0706
A41: 39994 | B41: =VLOOKUP($A41,[1]Burgiss_Return!$B:$P,MATCH(B$2,[1]Burgiss_Return!$B$5:$P$5,0),0) -> 0.0537 | C41: =VLOOKUP($A41,[1]Burgiss_Return!$B:$P,MATCH(C$2,[1]Burgiss_Return!$B$5:$P$5,0),0) -> 0.0115 | D41: =VLOOKUP($A41,[1]Burgiss_Return!$B:$P,MATCH(D$2,[1]Burgiss_Return!$B$5:$P$5,0),0) -> 0.0115 | E41: =VLOOKUP($A41,[1]Burgiss_Return!$B:$P,MATCH(E$2,[1]Burgiss_Return!$B$5:$P$5,0),0) -> -0.0242 | F41: =VLOOKUP($A41,[1]Burgiss_Return!$B:$P,MATCH(F$2,[1]Burgiss_Return!$B$5:$P$5,0),0) -> -0.0116 | G41: =VLOOKUP($A41,[1]Burgiss_Return!$B:$P,MATCH(G$2,[1]Burgiss_Return!$B$5:$P$5,0),0) -> -0.0242 | I41: =VLOOKUP($A41,[1]Burgiss_Return!$B:$P,MATCH(I$2,[1]Burgiss_Return!$B$5:$P$5,0),0) -> 0.2705 | J41: =VLOOKUP($A41,[1]Burgiss_Return!$B:$P,MATCH(J$2,[1]Burgiss_Return!$B$5:$P$5,0),0) -> 0.148 | K41: 0.03874805 | L41: -0.021386 | M41: =VLOOKUP($A41,[1]Burgiss_Return!$B:$P,MATCH(M$2,[1]Burgiss_Return!$B$5:$P$5,0),0) -> -0.1236 | N41: -0.021386 | Q41: 0.35905638 | R41: =VLOOKUP($A41,[1]Burgiss_Return!$B:$P,MATCH(R$2,[1]Burgiss_Return!$B$5:$P$5,0),0) -> 0.0405 | S41: =VLOOKUP($A41,[1]Burgiss_Return!$B:$P,MATCH(S$2,[1]Burgiss_Return!$B$5:$P$5,0),0) -> 0.0405 | T41: =VLOOKUP($A41,[1]Burgiss_Return!$B:$P,MATCH(T$2,[1]Burgiss_Return!$B$5:$P$5,0),0) -> 0.0405 | U41: =VLOOKUP($A41,[1]Burgiss_Return!$B:$P,MATCH(U$2,[1]Burgiss_Return!$B$5:$P$5,0),0) -> 0.0405
A42: 40086 | B42: =VLOOKUP($A42,[1]Burgiss_Return!$B:$P,MATCH(B$2,[1]Burgiss_Return!$B$5:$P$5,0),0) -> 0.0798 | C42: =VLOOKUP($A42,[1]Burgiss_Return!$B:$P,MATCH(C$2,[1]Burgiss_Return!$B$5:$P$5,0),0) -> 0.0173 | D42: =VLOOKUP($A42,[1]Burgiss_Return!$B:$P,MATCH(D$2,[1]Burgiss_Return!$B$5:$P$5,0),0) -> 0.0173 | E42: =VLOOKUP($A42,[1]Burgiss_Return!$B:$P,MATCH(E$2,[1]Burgiss_Return!$B$5:$P$5,0),0) -> 0.0257 | F42: =VLOOKUP($A42,[1]Burgiss_Return!$B:$P,MATCH(F$2,[1]Burgiss_Return!$B$5:$P$5,0),0) -> 0.0402 | G42: =VLOOKUP($A42,[1]Burgiss_Return!$B:$P,MATCH(G$2,[1]Burgiss_Return!$B$5:$P$5,0),0) -> 0.0257 | I42: =VLOOKUP($A42,[1]Burgiss_Return!$B:$P,MATCH(I$2,[1]Burgiss_Return!$B$5:$P$5,0),0) -> 0.1758 | J42: =VLOOKUP($A42,[1]Burgiss_Return!$B:$P,MATCH(J$2,[1]Burgiss_Return!$B$5:$P$5,0),0) -> 0.0744 | K42: 0.036810569 | L42: -0.023272 | M42: =VLOOKUP($A42,[1]Burgiss_Return!$B:$P,MATCH(M$2,[1]Burgiss_Return!$B$5:$P$5,0),0) -> -0.0386 | N42: -0.023272 | Q42: 0.25081974 | R42: =VLOOKUP($A42,[1]Burgiss_Return!$B:$P,MATCH(R$2,[1]Burgiss_Return!$B$5:$P$5,0),0) -> 0.019 | S42: =VLOOKUP($A42,[1]Burgiss_Return!$B:$P,MATCH(S$2,[1]Burgiss_Return!$B$5:$P$5,0),0) -> 0.019 | T42: =VLOOKUP($A42,[1]Burgiss_Return!$B:$P,MATCH(T$2,[1]Burgiss_Return!$B$5:$P$5,0),0) -> 0.019 | U42: =VLOOKUP($A42,[1]Burgiss_Return!$B:$P,MATCH(U$2,[1]Burgiss_Return!$B$5:$P$5,0),0) -> 0.019
A43: 40178 | B43: =VLOOKUP($A43,[1]Burgiss_Return!$B:$P,MATCH(B$2,[1]Burgiss_Return!$B$5:$P$5,0),0) -> 0.0649 | C43: =VLOOKUP($A43,[1]Burgiss_Return!$B:$P,MATCH(C$2,[1]Burgiss_Return!$B$5:$P$5,0),0) -> 0.043 | D43: =VLOOKUP($A43,[1]Burgiss_Return!$B:$P,MATCH(D$2,[1]Burgiss_Return!$B$5:$P$5,0),0) -> 0.043 | E43: =VLOOKUP($A43,[1]Burgiss_Return!$B:$P,MATCH(E$2,[1]Burgiss_Return!$B$5:$P$5,0),0) -> 0.0725 | F43: =VLOOKUP($A43,[1]Burgiss_Return!$B:$P,MATCH(F$2,[1]Burgiss_Return!$B$5:$P$5,0),0) -> 0.0506 | G43: =VLOOKUP($A43,[1]Burgiss_Return!$B:$P,MATCH(G$2,[1]Burgiss_Return!$B$5:$P$5,0),0) -> 0.0725 | I43: =VLOOKUP($A43,[1]Burgiss_Return!$B:$P,MATCH(I$2,[1]Burgiss_Return!$B$5:$P$5,0),0) -> 0.0867 | J43: =VLOOKUP($A43,[1]Burgiss_Return!$B:$P,MATCH(J$2,[1]Burgiss_Return!$B$5:$P$5,0),0) -> 0.1164 | K43: 0.010942709 | L43: -0.002224 | M43: =VLOOKUP($A43,[1]Burgiss_Return!$B:$P,MATCH(M$2,[1]Burgiss_Return!$B$5:$P$5,0),0) -> -0.1196 | N43: -0.002224 | Q43: 0.043954856 | R43: =VLOOKUP($A43,[1]Burgiss_Return!$B:$P,MATCH(R$2,[1]Burgiss_Return!$B$5:$P$5,0),0) -> -0.002 | S43: =VLOOKUP($A43,[1]Burgiss_Return!$B:$P,MATCH(S$2,[1]Burgiss_Return!$B$5:$P$5,0),0) -> -0.002 | T43: =VLOOKUP($A43,[1]Burgiss_Return!$B:$P,MATCH(T$2,[1]Burgiss_Return!$B$5:$P$5,0),0) -> -0.002 | U43: =VLOOKUP($A43,[1]Burgiss_Return!$B:$P,MATCH(U$2,[1]Burgiss_Return!$B$5:$P$5,0),0) -> -0.002
A44: 40268 | B44: =VLOOKUP($A44,[1]Burgiss_Return!$B:$P,MATCH(B$2,[1]Burgiss_Return!$B$5:$P$5,0),0) -> 0.0273 | C44: =VLOOKUP($A44,[1]Burgiss_Return!$B:$P,MATCH(C$2,[1]Burgiss_Return!$B$5:$P$5,0),0) -> 0.005 | D44: =VLOOKUP($A44,[1]Burgiss_Return!$B:$P,MATCH(D$2,[1]Burgiss_Return!$B$5:$P$5,0),0) -> 0.005 | E44: =VLOOKUP($A44,[1]Burgiss_Return!$B:$P,MATCH(E$2,[1]Burgiss_Return!$B$5:$P$5,0),0) -> 0.0169 | F44: =VLOOKUP($A44,[1]Burgiss_Return!$B:$P,MATCH(F$2,[1]Burgiss_Return!$B$5:$P$5,0),0) -> 0.0106 | G44: =VLOOKUP($A44,[1]Burgiss_Return!$B:$P,MATCH(G$2,[1]Burgiss_Return!$B$5:$P$5,0),0) -> 0.0169 | I44: =VLOOKUP($A44,[1]Burgiss_Return!$B:$P,MATCH(I$2,[1]Burgiss_Return!$B$5:$P$5,0),0) -> 0.055 | J44: =VLOOKUP($A44,[1]Burgiss_Return!$B:$P,MATCH(J$2,[1]Burgiss_Return!$B$5:$P$5,0),0) -> 0.0394 | K44: 0.016997172 | L44: 0.005386 | M44: =VLOOKUP($A44,[1]Burgiss_Return!$B:$P,MATCH(M$2,[1]Burgiss_Return!$B$5:$P$5,0),0) -> 0.0051 | N44: 0.005386 | Q44: 0.039655244 | R44: =VLOOKUP($A44,[1]Burgiss_Return!$B:$P,MATCH(R$2,[1]Burgiss_Return!$B$5:$P$5,0),0) -> -0.0115 | S44: =VLOOKUP($A44,[1]Burgiss_Return!$B:$P,MATCH(S$2,[1]Burgiss_Return!$B$5:$P$5,0),0) -> -0.0115 | T44: =VLOOKUP($A44,[1]Burgiss_Return!$B:$P,MATCH(T$2,[1]Burgiss_Return!$B$5:$P$5,0),0) -> -0.0115 | U44: =VLOOKUP($A44,[1]Burgiss_Return!$B:$P,MATCH(U$2,[1]Burgiss_Return!$B$5:$P$5,0),0) -> -0.0115
A45: 40359 | B45: =VLOOKUP($A45,[1]Burgiss_Return!$B:$P,MATCH(B$2,[1]Burgiss_Return!$B$5:$P$5,0),0) -> 0.0015 | C45: =VLOOKUP($A45,[1]Burgiss_Return!$B:$P,MATCH(C$2,[1]Burgiss_Return!$B$5:$P$5,0),0) -> -0.0011 | D45: =VLOOKUP($A45,[1]Burgiss_Return!$B:$P,MATCH(D$2,[1]Burgiss_Return!$B$5:$P$5,0),0) -> -0.0011 | E45: =VLOOKUP($A45,[1]Burgiss_Return!$B:$P,MATCH(E$2,[1]Burgiss_Return!$B$5:$P$5,0),0) -> 0.0211 | F45: =VLOOKUP($A45,[1]Burgiss_Return!$B:$P,MATCH(F$2,[1]Burgiss_Return!$B$5:$P$5,0),0) -> -0.0104 | G45: =VLOOKUP($A45,[1]Burgiss_Return!$B:$P,MATCH(G$2,[1]Burgiss_Return!$B$5:$P$5,0),0) -> 0.0211 | H45: =VLOOKUP($A45,[1]Burgiss_Return!$B:$P,MATCH(H$2,[1]Burgiss_Return!$B$5:$P$5,0),0) -> -0.0188 | I45: =VLOOKUP($A45,[1]Burgiss_Return!$B:$P,MATCH(I$2,[1]Burgiss_Return!$B$5:$P$5,0),0) -> -0.0172 | J45: =VLOOKUP($A45,[1]Burgiss_Return!$B:$P,MATCH(J$2,[1]Burgiss_Return!$B$5:$P$5,0),0) -> 0.0114 | K45: -0.015008741 | L45: 0.002125 | M45: =VLOOKUP($A45,[1]Burgiss_Return!$B:$P,MATCH(M$2,[1]Burgiss_Return!$B$5:$P$5,0),0) -> 0.0343 | N45: 0.002125 | Q45: -0.078864089 | R45: =VLOOKUP($A45,[1]Burgiss_Return!$B:$P,MATCH(R$2,[1]Burgiss_Return!$B$5:$P$5,0),0) -> -0.0019 | S45: =VLOOKUP($A45,[1]Burgiss_Return!$B:$P,MATCH(S$2,[1]Burgiss_Return!$B$5:$P$5,0),0) -> -0.0019 | T45: =VLOOKUP($A45,[1]Burgiss_Return!$B:$P,MATCH(T$2,[1]Burgiss_Return!$B$5:$P$5,0),0) -> -0.0019 | U45: =VLOOKUP($A45,[1]Burgiss_Return!$B:$P,MATCH(U$2,[1]Burgiss_Return!$B$5:$P$5,0),0) -> -0.0019 | V45: 0.04366506
A46: 40451 | B46: =VLOOKUP($A46,[1]Burgiss_Return!$B:$P,MATCH(B$2,[1]Burgiss_Return!$B$5:$P$5,0),0) -> 0.0689 | C46: =VLOOKUP($A46,[1]Burgiss_Return!$B:$P,MATCH(C$2,[1]Burgiss_Return!$B$5:$P$5,0),0) -> 0.0408 | D46: =VLOOKUP($A46,[1]Burgiss_Return!$B:$P,MATCH(D$2,[1]Burgiss_Return!$B$5:$P$5,0),0) -> 0.0408 | E46: =VLOOKUP($A46,[1]Burgiss_Return!$B:$P,MATCH(E$2,[1]Burgiss_Return!$B$5:$P$5,0),0) -> 0.0613 | F46: =VLOOKUP($A46,[1]Burgiss_Return!$B:$P,MATCH(F$2,[1]Burgiss_Return!$B$5:$P$5,0),0) -> 0.0662 | G46: =VLOOKUP($A46,[1]Burgiss_Return!$B:$P,MATCH(G$2,[1]Burgiss_Return!$B$5:$P$5,0),0) -> 0.0613 | H46: =VLOOKUP($A46,[1]Burgiss_Return!$B:$P,MATCH(H$2,[1]Burgiss_Return!$B$5:$P$5,0),0) -> 0.0638 | I46: =VLOOKUP($A46,[1]Burgiss_Return!$B:$P,MATCH(I$2,[1]Burgiss_Return!$B$5:$P$5,0),0) -> 0.0502 | J46: =VLOOKUP($A46,[1]Burgiss_Return!$B:$P,MATCH(J$2,[1]Burgiss_Return!$B$5:$P$5,0),0) -> 0.1076 | K46: 0.022504337 | L46: 0.092945 | M46: =VLOOKUP($A46,[1]Burgiss_Return!$B:$P,MATCH(M$2,[1]Burgiss_Return!$B$5:$P$5,0),0) -> 0.0559 | N46: 0.092945 | Q46: 0.18440763 | R46: =VLOOKUP($A46,[1]Burgiss_Return!$B:$P,MATCH(R$2,[1]Burgiss_Return!$B$5:$P$5,0),0) -> 0.0878 | S46: =VLOOKUP($A46,[1]Burgiss_Return!$B:$P,MATCH(S$2,[1]Burgiss_Return!$B$5:$P$5,0),0) -> 0.0878 | T46: =VLOOKUP($A46,[1]Burgiss_Return!$B:$P,MATCH(T$2,[1]Burgiss_Return!$B$5:$P$5,0),0) -> 0.0878 | U46: =VLOOKUP($A46,[1]Burgiss_Return!$B:$P,MATCH(U$2,[1]Burgiss_Return!$B$5:$P$5,0),0) -> 0.0878 | V46: 0.042870227
...

Sheet Main
A1: Date | B1: Buyout | C1: Growth | D1: Venture Capital | E1: Fund of Fund | F1: Long-term Core | G1: GP-Stake / Continuation Vehicle | H1: Senior Credit | I1: Junior Credit | J1: 국내 사모투자 | K1: Hedge Fund | L1: Core RE Equity | M1: Non-Core RE Equity | N1: 국내 부동산 | O1: Core RE Debt | P1: Non-Core RE Debt | Q1: Listed RE | R1: Core 국내 인프라 | S1: Non-Core 국내 인프라 | T1: Core 해외 인프라 | U1: Non-Core 해외 인프라 | V1: Super-Core Infrastructure
A2: 36616 | B2: =IF(VLOOKUP($A2,값!$A:$W,MATCH(Main!B$1,값!$2:$2,0),0)="",NA(),VLOOKUP($A2,값!$A:$W,MATCH(Main!B$1,값!$2:$2,0),0)) -> 0.1103 | C2: =IF(VLOOKUP($A2,값!$A:$W,MATCH(Main!C$1,값!$2:$2,0),0)="",NA(),VLOOKUP($A2,값!$A:$W,MATCH(Main!C$1,값!$2:$2,0),0)) -> 0.1533 | D2: =IF(VLOOKUP($A2,값!$A:$W,MATCH(Main!D$1,값!$2:$2,0),0)="",NA(),VLOOKUP($A2,값!$A:$W,MATCH(Main!D$1,값!$2:$2,0),0)) -> 0.1533 | E2: =IF(VLOOKUP($A2,값!$A:$W,MATCH(Main!E$1,값!$2:$2,0),0)="",NA(),VLOOKUP($A2,값!$A:$W,MATCH(Main!E$1,값!$2:$2,0),0)) -> #N/A | F2: =IF(VLOOKUP($A2,값!$A:$W,MATCH(Main!F$1,값!$2:$2,0),0)="",NA(),VLOOKUP($A2,값!$A:$W,MATCH(Main!F$1,값!$2:$2,0),0)) -> 0.0053 | G2: =IF(VLOOKUP($A2,값!$A:$W,MATCH(Main!G$1,값!$2:$2,0),0)="",NA(),VLOOKUP($A2,값!$A:$W,MATCH(Main!G$1,값!$2:$2,0),0)) -> #N/A | H2: =IF(VLOOKUP($A2,값!$A:$W,MATCH(Main!H$1,값!$2:$2,0),0)="",NA(),VLOOKUP($A2,값!$A:$W,MATCH(Main!H$1,값!$2:$2,0),0)) -> #N/A | I2: =IF(VLOOKUP($A2,값!$A:$W,MATCH(Main!I$1,값!$2:$2,0),0)="",NA(),VLOOKUP($A2,값!$A:$W,MATCH(Main!I$1,값!$2:$2,0),0)) -> 0.0114 | ... V2: =IF(VLOOKUP($A2,값!$A:$W,MATCH(Main!V$1,값!$2:$2,0),0)="",NA(),VLOOKUP($A2,값!$A:$W,MATCH(Main!V$1,값!$2:$2,0),0)) -> #N/A
A3: 36707 | B3: =IF(VLOOKUP($A3,값!$A:$W,MATCH(Main!B$1,값!$2:$2,0),0)="",NA(),VLOOKUP($A3,값!$A:$W,MATCH(Main!B$1,값!$2:$2,0),0)) -> -0.0009 | C3: =IF(VLOOKUP($A3,값!$A:$W,MATCH(Main!C$1,값!$2:$2,0),0)="",NA(),VLOOKUP($A3,값!$A:$W,MATCH(Main!C$1,값!$2:$2,0),0)) -> 0.0751 | D3: =IF(VLOOKUP($A3,값!$A:$W,MATCH(Main!D$1,값!$2:$2,0),0)="",NA(),VLOOKUP($A3,값!$A:$W,MATCH(Main!D$1,값!$2:$2,0),0)) -> 0.0751 | E3: =IF(VLOOKUP($A3,값!$A:$W,MATCH(Main!E$1,값!$2:$2,0),0)="",NA(),VLOOKUP($A3,값!$A:$W,MATCH(Main!E$1,값!$2:$2,0),0)) -> #N/A | F3: =IF(VLOOKUP($A3,값!$A:$W,MATCH(Main!F$1,값!$2:$2,0),0)="",NA(),VLOOKUP($A3,값!$A:$W,MATCH(Main!F$1,값!$2:$2,0),0)) -> 0.0363 | G3: =IF(VLOOKUP($A3,값!$A:$W,MATCH(Main!G$1,값!$2:$2,0),0)="",NA(),VLOOKUP($A3,값!$A:$W,MATCH(Main!G$1,값!$2:$2,0),0)) -> #N/A | H3: =IF(VLOOKUP($A3,값!$A:$W,MATCH(Main!H$1,값!$2:$2,0),0)="",NA(),VLOOKUP($A3,값!$A:$W,MATCH(Main!H$1,값!$2:$2,0),0)) -> #N/A | I3: =IF(VLOOKUP($A3,값!$A:$W,MATCH(Main!I$1,값!$2:$2,0),0)="",NA(),VLOOKUP($A3,값!$A:$W,MATCH(Main!I$1,값!$2:$2,0),0)) -> 0.0159 | ... V3: =IF(VLOOKUP($A3,값!$A:$W,MATCH(Main!V$1,값!$2:$2,0),0)="",NA(),VLOOKUP($A3,값!$A:$W,MATCH(Main!V$1,값!$2:$2,0),0)) -> #N/A
A4: 36799 | B4: =IF(VLOOKUP($A4,값!$A:$W,MATCH(Main!B$1,값!$2:$2,0),0)="",NA(),VLOOKUP($A4,값!$A:$W,MATCH(Main!B$1,값!$2:$2,0),0)) -> -0.0295 | C4: =IF(VLOOKUP($A4,값!$A:$W,MATCH(Main!C$1,값!$2:$2,0),0)="",NA(),VLOOKUP($A4,값!$A:$W,MATCH(Main!C$1,값!$2:$2,0),0)) -> 0.1497 | D4: =IF(VLOOKUP($A4,값!$A:$W,MATCH(Main!D$1,값!$2:$2,0),0)="",NA(),VLOOKUP($A4,값!$A:$W,MATCH(Main!D$1,값!$2:$2,0),0)) -> 0.1497 | E4: =IF(VLOOKUP($A4,값!$A:$W,MATCH(Main!E$1,값!$2:$2,0),0)="",NA(),VLOOKUP($A4,값!$A:$W,MATCH(Main!E$1,값!$2:$2,0),0)) -> #N/A | F4: =IF(VLOOKUP($A4,값!$A:$W,MATCH(Main!F$1,값!$2:$2,0),0)="",NA(),VLOOKUP($A4,값!$A:$W,MATCH(Main!F$1,값!$2:$2,0),0)) -> 0.0089 | G4: =IF(VLOOKUP($A4,값!$A:$W,MATCH(Main!G$1,값!$2:$2,0),0)="",NA(),VLOOKUP($A4,값!$A:$W,MATCH(Main!G$1,값!$2:$2,0),0)) -> #N/A | H4: =IF(VLOOKUP($A4,값!$A:$W,MATCH(Main!H$1,값!$2:$2,0),0)="",NA(),VLOOKUP($A4,값!$A:$W,MATCH(Main!H$1,값!$2:$2,0),0)) -> #N/A | I4: =IF(VLOOKUP($A4,값!$A:$W,MATCH(Main!I$1,값!$2:$2,0),0)="",NA(),VLOOKUP($A4,값!$A:$W,MATCH(Main!I$1,값!$2:$2,0),0)) -> 0.0368 | ... V4: =IF(VLOOKUP($A4,값!$A:$W,MATCH(Main!V$1,값!$2:$2,0),0)="",NA(),VLOOKUP($A4,값!$A:$W,MATCH(Main!V$1,값!$2:$2,0),0)) -> #N/A
A5: 36891 | B5: =IF(VLOOKUP($A5,값!$A:$W,MATCH(Main!B$1,값!$2:$2,0),0)="",NA(),VLOOKUP($A5,값!$A:$W,MATCH(Main!B$1,값!$2:$2,0),0)) -> -0.0306 | C5: =IF(VLOOKUP($A5,값!$A:$W,MATCH(Main!C$1,값!$2:$2,0),0)="",NA(),VLOOKUP($A5,값!$A:$W,MATCH(Main!C$1,값!$2:$2,0),0)) -> -0.1013 | D5: =IF(VLOOKUP($A5,값!$A:$W,MATCH(Main!D$1,값!$2:$2,0),0)="",NA(),VLOOKUP($A5,값!$A:$W,MATCH(Main!D$1,값!$2:$2,0),0)) -> -0.1013 | E5: =IF(VLOOKUP($A5,값!$A:$W,MATCH(Main!E$1,값!$2:$2,0),0)="",NA(),VLOOKUP($A5,값!$A:$W,MATCH(Main!E$1,값!$2:$2,0),0)) -> #N/A | F5: =IF(VLOOKUP($A5,값!$A:$W,MATCH(Main!F$1,값!$2:$2,0),0)="",NA(),VLOOKUP($A5,값!$A:$W,MATCH(Main!F$1,값!$2:$2,0),0)) -> -0.0575 | G5: =IF(VLOOKUP($A5,값!$A:$W,MATCH(Main!G$1,값!$2:$2,0),0)="",NA(),VLOOKUP($A5,값!$A:$W,MATCH(Main!G$1,값!$2:$2,0),0)) -> #N/A | H5: =IF(VLOOKUP($A5,값!$A:$W,MATCH(Main!H$1,값!$2:$2,0),0)="",NA(),VLOOKUP($A5,값!$A:$W,MATCH(Main!H$1,값!$2:$2,0),0)) -> #N/A | I5: =IF(VLOOKUP($A5,값!$A:$W,MATCH(Main!I$1,값!$2:$2,0),0)="",NA(),VLOOKUP($A5,값!$A:$W,MATCH(Main!I$1,값!$2:$2,0),0)) -> -0.0183 | ... V5: =IF(VLOOKUP($A5,값!$A:$W,MATCH(Main!V$1,값!$2:$2,0),0)="",NA(),VLOOKUP($A5,값!$A:$W,MATCH(Main!V$1,값!$2:$2,0),0)) -> #N/A
A6: 36981 | B6: =IF(VLOOKUP($A6,값!$A:$W,MATCH(Main!B$1,값!$2:$2,0),0)="",NA(),VLOOKUP($A6,값!$A:$W,MATCH(Main!B$1,값!$2:$2,0),0)) -> -0.0635 | C6: =IF(VLOOKUP($A6,값!$A:$W,MATCH(Main!C$1,값!$2:$2,0),0)="",NA(),VLOOKUP($A6,값!$A:$W,MATCH(Main!C$1,값!$2:$2,0),0)) -> -0.0899 | D6: =IF(VLOOKUP($A6,값!$A:$W,MATCH(Main!D$1,값!$2:$2,0),0)="",NA(),VLOOKUP($A6,값!$A:$W,MATCH(Main!D$1,값!$2:$2,0),0)) -> -0.0899 | E6: =IF(VLOOKUP($A6,값!$A:$W,MATCH(Main!E$1,값!$2:$2,0),0)="",NA(),VLOOKUP($A6,값!$A:$W,MATCH(Main!E$1,값!$2:$2,0),0)) -> #N/A | F6: =IF(VLOOKUP($A6,값!$A:$W,MATCH(Main!F$1,값!$2:$2,0),0)="",NA(),VLOOKUP($A6,값!$A:$W,MATCH(Main!F$1,값!$2:$2,0),0)) -> -0.0119 | G6: =IF(VLOOKUP($A6,값!$A:$W,MATCH(Main!G$1,값!$2:$2,0),0)="",NA(),VLOOKUP($A6,값!$A:$W,MATCH(Main!G$1,값!$2:$2,0),0)) -> #N/A | H6: =IF(VLOOKUP($A6,값!$A:$W,MATCH(Main!H$1,값!$2:$2,0),0)="",NA(),VLOOKUP($A6,값!$A:$W,MATCH(Main!H$1,값!$2:$2,0),0)) -> #N/A | I6: =IF(VLOOKUP($A6,값!$A:$W,MATCH(Main!I$1,값!$2:$2,0),0)="",NA(),VLOOKUP($A6,값!$A:$W,MATCH(Main!I$1,값!$2:$2,0),0)) -> 0.0647 | ... V6: =IF(VLOOKUP($A6,값!$A:$W,MATCH(Main!V$1,값!$2:$2,0),0)="",NA(),VLOOKUP($A6,값!$A:$W,MATCH(Main!V$1,값!$2:$2,0),0)) -> #N/A
A7: 37072 | B7: =IF(VLOOKUP($A7,값!$A:$W,MATCH(Main!B$1,값!$2:$2,0),0)="",NA(),VLOOKUP($A7,값!$A:$W,MATCH(Main!B$1,값!$2:$2,0),0)) -> 0.0238 | C7: =IF(VLOOKUP($A7,값!$A:$W,MATCH(Main!C$1,값!$2:$2,0),0)="",NA(),VLOOKUP($A7,값!$A:$W,MATCH(Main!C$1,값!$2:$2,0),0)) -> -0.0746 | D7: =IF(VLOOKUP($A7,값!$A:$W,MATCH(Main!D$1,값!$2:$2,0),0)="",NA(),VLOOKUP($A7,값!$A:$W,MATCH(Main!D$1,값!$2:$2,0),0)) -> -0.0746 | E7: =IF(VLOOKUP($A7,값!$A:$W,MATCH(Main!E$1,값!$2:$2,0),0)="",NA(),VLOOKUP($A7,값!$A:$W,MATCH(Main!E$1,값!$2:$2,0),0)) -> #N/A | F7: =IF(VLOOKUP($A7,값!$A:$W,MATCH(Main!F$1,값!$2:$2,0),0)="",NA(),VLOOKUP($A7,값!$A:$W,MATCH(Main!F$1,값!$2:$2,0),0)) -> -0.0608 | G7: =IF(VLOOKUP($A7,값!$A:$W,MATCH(Main!G$1,값!$2:$2,0),0)="",NA(),VLOOKUP($A7,값!$A:$W,MATCH(Main!G$1,값!$2:$2,0),0)) -> #N/A | H7: =IF(VLOOKUP($A7,값!$A:$W,MATCH(Main!H$1,값!$2:$2,0),0)="",NA(),VLOOKUP($A7,값!$A:$W,MATCH(Main!H$1,값!$2:$2,0),0)) -> #N/A | I7: =IF(VLOOKUP($A7,값!$A:$W,MATCH(Main!I$1,값!$2:$2,0),0)="",NA(),VLOOKUP($A7,값!$A:$W,MATCH(Main!I$1,값!$2:$2,0),0)) -> 0.029 | ... V7: =IF(VLOOKUP($A7,값!$A:$W,MATCH(Main!V$1,값!$2:$2,0),0)="",NA(),VLOOKUP($A7,값!$A:$W,MATCH(Main!V$1,값!$2:$2,0),0)) -> #N/A
A8: 37164 | B8: =IF(VLOOKUP($A8,값!$A:$W,MATCH(Main!B$1,값!$2:$2,0),0)="",NA(),VLOOKUP($A8,값!$A:$W,MATCH(Main!B$1,값!$2:$2,0),0)) -> -0.0809 | C8: =IF(VLOOKUP($A8,값!$A:$W,MATCH(Main!C$1,값!$2:$2,0),0)="",NA(),VLOOKUP($A8,값!$A:$W,MATCH(Main!C$1,값!$2:$2,0),0)) -> -0.1505 | D8: =IF(VLOOKUP($A8,값!$A:$W,MATCH(Main!D$1,값!$2:$2,0),0)="",NA(),VLOOKUP($A8,값!$A:$W,MATCH(Main!D$1,값!$2:$2,0),0)) -> -0.1505 | E8: =IF(VLOOKUP($A8,값!$A:$W,MATCH(Main!E$1,값!$2:$2,0),0)="",NA(),VLOOKUP($A8,값!$A:$W,MATCH(Main!E$1,값!$2:$2,0),0)) -> #N/A | F8: =IF(VLOOKUP($A8,값!$A:$W,MATCH(Main!F$1,값!$2:$2,0),0)="",NA(),VLOOKUP($A8,값!$A:$W,MATCH(Main!F$1,값!$2:$2,0),0)) -> -0.0545 | G8: =IF(VLOOKUP($A8,값!$A:$W,MATCH(Main!G$1,값!$2:$2,0),0)="",NA(),VLOOKUP($A8,값!$A:$W,MATCH(Main!G$1,값!$2:$2,0),0)) -> #N/A | H8: =IF(VLOOKUP($A8,값!$A:$W,MATCH(Main!H$1,값!$2:$2,0),0)="",NA(),VLOOKUP($A8,값!$A:$W,MATCH(Main!H$1,값!$2:$2,0),0)) -> #N/A | I8: =IF(VLOOKUP($A8,값!$A:$W,MATCH(Main!I$1,값!$2:$2,0),0)="",NA(),VLOOKUP($A8,값!$A:$W,MATCH(Main!I$1,값!$2:$2,0),0)) -> 0.0149 | ... V8: =IF(VLOOKUP($A8,값!$A:$W,MATCH(Main!V$1,값!$2:$2,0),0)="",NA(),VLOOKUP($A8,값!$A:$W,MATCH(Main!V$1,값!$2:$2,0),0)) -> #N/A
A9: 37256 | B9: =IF(VLOOKUP($A9,값!$A:$W,MATCH(Main!B$1,값!$2:$2,0),0)="",NA(),VLOOKUP($A9,값!$A:$W,MATCH(Main!B$1,값!$2:$2,0),0)) -> -0.0011 | C9: =IF(VLOOKUP($A9,값!$A:$W,MATCH(Main!C$1,값!$2:$2,0),0)="",NA(),VLOOKUP($A9,값!$A:$W,MATCH(Main!C$1,값!$2:$2,0),0)) -> -0.0779 | D9: =IF(VLOOKUP($A9,값!$A:$W,MATCH(Main!D$1,값!$2:$2,0),0)="",NA(),VLOOKUP($A9,값!$A:$W,MATCH(Main!D$1,값!$2:$2,0),0)) -> -0.0779 | E9: =IF(VLOOKUP($A9,값!$A:$W,MATCH(Main!E$1,값!$2:$2,0),0)="",NA(),VLOOKUP($A9,값!$A:$W,MATCH(Main!E$1,값!$2:$2,0),0)) -> #N/A | F9: =IF(VLOOKUP($A9,값!$A:$W,MATCH(Main!F$1,값!$2:$2,0),0)="",NA(),VLOOKUP($A9,값!$A:$W,MATCH(Main!F$1,값!$2:$2,0),0)) -> -0.0812 | G9: =IF(VLOOKUP($A9,값!$A:$W,MATCH(Main!G$1,값!$2:$2,0),0)="",NA(),VLOOKUP($A9,값!$A:$W,MATCH(Main!G$1,값!$2:$2,0),0)) -> #N/A | H9: =IF(VLOOKUP($A9,값!$A:$W,MATCH(Main!H$1,값!$2:$2,0),0)="",NA(),VLOOKUP($A9,값!$A:$W,MATCH(Main!H$1,값!$2:$2,0),0)) -> #N/A | I9: =IF(VLOOKUP($A9,값!$A:$W,MATCH(Main!I$1,값!$2:$2,0),0)="",NA(),VLOOKUP($A9,값!$A:$W,MATCH(Main!I$1,값!$2:$2,0),0)) -> 0.021 | ... V9: =IF(VLOOKUP($A9,값!$A:$W,MATCH(Main!V$1,값!$2:$2,0),0)="",NA(),VLOOKUP($A9,값!$A:$W,MATCH(Main!V$1,값!$2:$2,0),0)) -> #N/A
A10: 37346 | B10: =IF(VLOOKUP($A10,값!$A:$W,MATCH(Main!B$1,값!$2:$2,0),0)="",NA(),VLOOKUP($A10,값!$A:$W,MATCH(Main!B$1,값!$2:$2,0),0)) -> -0.0023 | C10: =IF(VLOOKUP($A10,값!$A:$W,MATCH(Main!C$1,값!$2:$2,0),0)="",NA(),VLOOKUP($A10,값!$A:$W,MATCH(Main!C$1,값!$2:$2,0),0)) -> -0.0948 | D10: =IF(VLOOKUP($A10,값!$A:$W,MATCH(Main!D$1,값!$2:$2,0),0)="",NA(),VLOOKUP($A10,값!$A:$W,MATCH(Main!D$1,값!$2:$2,0),0)) -> -0.0948 | E10: =IF(VLOOKUP($A10,값!$A:$W,MATCH(Main!E$1,값!$2:$2,0),0)="",NA(),VLOOKUP($A10,값!$A:$W,MATCH(Main!E$1,값!$2:$2,0),0)) -> 0.0327 | F10: =IF(VLOOKUP($A10,값!$A:$W,MATCH(Main!F$1,값!$2:$2,0),0)="",NA(),VLOOKUP($A10,값!$A:$W,MATCH(Main!F$1,값!$2:$2,0),0)) -> -0.025 | G10: =IF(VLOOKUP($A10,값!$A:$W,MATCH(Main!G$1,값!$2:$2,0),0)="",NA(),VLOOKUP($A10,값!$A:$W,MATCH(Main!G$1,값!$2:$2,0),0)) -> 0.0327 | H10: =IF(VLOOKUP($A10,값!$A:$W,MATCH(Main!H$1,값!$2:$2,0),0)="",NA(),VLOOKUP($A10,값!$A:$W,MATCH(Main!H$1,값!$2:$2,0),0)) -> #N/A | I10: =IF(VLOOKUP($A10,값!$A:$W,MATCH(Main!I$1,값!$2:$2,0),0)="",NA(),VLOOKUP($A10,값!$A:$W,MATCH(Main!I$1,값!$2:$2,0),0)) -> 0.0377 | ... V10: =IF(VLOOKUP($A10,값!$A:$W,MATCH(Main!V$1,값!$2:$2,0),0)="",NA(),VLOOKUP($A10,값!$A:$W,MATCH(Main!V$1,값!$2:$2,0),0)) -> #N/A
A11: 37437 | B11: =IF(VLOOKUP($A11,값!$A:$W,MATCH(Main!B$1,값!$2:$2,0),0)="",NA(),VLOOKUP($A11,값!$A:$W,MATCH(Main!B$1,값!$2:$2,0),0)) -> -0.0135 | C11: =IF(VLOOKUP($A11,값!$A:$W,MATCH(Main!C$1,값!$2:$2,0),0)="",NA(),VLOOKUP($A11,값!$A:$W,MATCH(Main!C$1,값!$2:$2,0),0)) -> -0.1303 | D11: =IF(VLOOKUP($A11,값!$A:$W,MATCH(Main!D$1,값!$2:$2,0),0)="",NA(),VLOOKUP($A11,값!$A:$W,MATCH(Main!D$1,값!$2:$2,0),0)) -> -0.1303 | E11: =IF(VLOOKUP($A11,값!$A:$W,MATCH(Main!E$1,값!$2:$2,0),0)="",NA(),VLOOKUP($A11,값!$A:$W,MATCH(Main!E$1,값!$2:$2,0),0)) -> 0.0174 | F11: =IF(VLOOKUP($A11,값!$A:$W,MATCH(Main!F$1,값!$2:$2,0),0)="",NA(),VLOOKUP($A11,값!$A:$W,MATCH(Main!F$1,값!$2:$2,0),0)) -> -0.0711 | G11: =IF(VLOOKUP($A11,값!$A:$W,MATCH(Main!G$1,값!$2:$2,0),0)="",NA(),VLOOKUP($A11,값!$A:$W,MATCH(Main!G$1,값!$2:$2,0),0)) -> 0.0174 | H11: =IF(VLOOKUP($A11,값!$A:$W,MATCH(Main!H$1,값!$2:$2,0),0)="",NA(),VLOOKUP($A11,값!$A:$W,MATCH(Main!H$1,값!$2:$2,0),0)) -> #N/A | I11: =IF(VLOOKUP($A11,값!$A:$W,MATCH(Main!I$1,값!$2:$2,0),0)="",NA(),VLOOKUP($A11,값!$A:$W,MATCH(Main!I$1,값!$2:$2,0),0)) -> -0.001 | ... V11: =IF(VLOOKUP($A11,값!$A:$W,MATCH(Main!V$1,값!$2:$2,0),0)="",NA(),VLOOKUP($A11,값!$A:$W,MATCH(Main!V$1,값!$2:$2,0),0)) -> #N/A
A12: 37529 | B12: =IF(VLOOKUP($A12,값!$A:$W,MATCH(Main!B$1,값!$2:$2,0),0)="",NA(),VLOOKUP($A12,값!$A:$W,MATCH(Main!B$1,값!$2:$2,0),0)) -> -0.0398 | C12: =IF(VLOOKUP($A12,값!$A:$W,MATCH(Main!C$1,값!$2:$2,0),0)="",NA(),VLOOKUP($A12,값!$A:$W,MATCH(Main!C$1,값!$2:$2,0),0)) -> -0.0991 | D12: =IF(VLOOKUP($A12,값!$A:$W,MATCH(Main!D$1,값!$2:$2,0),0)="",NA(),VLOOKUP($A12,값!$A:$W,MATCH(Main!D$1,값!$2:$2,0),0)) -> -0.0991 | E12: =IF(VLOOKUP($A12,값!$A:$W,MATCH(Main!E$1,값!$2:$2,0),0)="",NA(),VLOOKUP($A12,값!$A:$W,MATCH(Main!E$1,값!$2:$2,0),0)) -> -0.0334 | F12: =IF(VLOOKUP($A12,값!$A:$W,MATCH(Main!F$1,값!$2:$2,0),0)="",NA(),VLOOKUP($A12,값!$A:$W,MATCH(Main!F$1,값!$2:$2,0),0)) -> -0.0593 | G12: =IF(VLOOKUP($A12,값!$A:$W,MATCH(Main!G$1,값!$2:$2,0),0)="",NA(),VLOOKUP($A12,값!$A:$W,MATCH(Main!G$1,값!$2:$2,0),0)) -> -0.0334 | H12: =IF(VLOOKUP($A12,값!$A:$W,MATCH(Main!H$1,값!$2:$2,0),0)="",NA(),VLOOKUP($A12,값!$A:$W,MATCH(Main!H$1,값!$2:$2,0),0)) -> #N/A | I12: =IF(VLOOKUP($A12,값!$A:$W,MATCH(Main!I$1,값!$2:$2,0),0)="",NA(),VLOOKUP($A12,값!$A:$W,MATCH(Main!I$1,값!$2:$2,0),0)) -> -0.0519 | ... V12: =IF(VLOOKUP($A12,값!$A:$W,MATCH(Main!V$1,값!$2:$2,0),0)="",NA(),VLOOKUP($A12,값!$A:$W,MATCH(Main!V$1,값!$2:$2,0),0)) -> #N/A
A13: 37621 | B13: =IF(VLOOKUP($A13,값!$A:$W,MATCH(Main!B$1,값!$2:$2,0),0)="",NA(),VLOOKUP($A13,값!$A:$W,MATCH(Main!B$1,값!$2:$2,0),0)) -> 0.0208 | C13: =IF(VLOOKUP($A13,값!$A:$W,MATCH(Main!C$1,값!$2:$2,0),0)="",NA(),VLOOKUP($A13,값!$A:$W,MATCH(Main!C$1,값!$2:$2,0),0)) -> -0.1076 | D13: =IF(VLOOKUP($A13,값!$A:$W,MATCH(Main!D$1,값!$2:$2,0),0)="",NA(),VLOOKUP($A13,값!$A:$W,MATCH(Main!D$1,값!$2:$2,0),0)) -> -0.1076 | E13: =IF(VLOOKUP($A13,값!$A:$W,MATCH(Main!E$1,값!$2:$2,0),0)="",NA(),VLOOKUP($A13,값!$A:$W,MATCH(Main!E$1,값!$2:$2,0),0)) -> -0.0336 | F13: =IF(VLOOKUP($A13,값!$A:$W,MATCH(Main!F$1,값!$2:$2,0),0)="",NA(),VLOOKUP($A13,값!$A:$W,MATCH(Main!F$1,값!$2:$2,0),0)) -> -0.0763 | G13: =IF(VLOOKUP($A13,값!$A:$W,MATCH(Main!G$1,값!$2:$2,0),0)="",NA(),VLOOKUP($A13,값!$A:$W,MATCH(Main!G$1,값!$2:$2,0),0)) -> -0.0336 | H13: =IF(VLOOKUP($A13,값!$A:$W,MATCH(Main!H$1,값!$2:$2,0),0)="",NA(),VLOOKUP($A13,값!$A:$W,MATCH(Main!H$1,값!$2:$2,0),0)) -> #N/A | I13: =IF(VLOOKUP($A13,값!$A:$W,MATCH(Main!I$1,값!$2:$2,0),0)="",NA(),VLOOKUP($A13,값!$A:$W,MATCH(Main!I$1,값!$2:$2,0),0)) -> 0.0741 | ... V13: =IF(VLOOKUP($A13,값!$A:$W,MATCH(Main!V$1,값!$2:$2,0),0)="",NA(),VLOOKUP($A13,값!$A:$W,MATCH(Main!V$1,값!$2:$2,0),0)) -> #N/A
... A106: 46112 | B106: =IF(VLOOKUP($A106,값!$A:$W,MATCH(Main!B$1,값!$2:$2,0),0)="",NA(),VLOOKUP($A106,값!$A:$W,MATCH(Main!B$1,값!$2:$2,0),0)) -> -0.0092 | C106: =IF(VLOOKUP($A106,값!$A:$W,MATCH(Main!C$1,값!$2:$2,0),0)="",NA(),VLOOKUP($A106,값!$A:$W,MATCH(Main!C$1,값!$2:$2,0),0)) -> 0.0381 | D106: =IF(VLOOKUP($A106,값!$A:$W,MATCH(Main!D$1,값!$2:$2,0),0)="",NA(),VLOOKUP($A106,값!$A:$W,MATCH(Main!D$1,값!$2:$2,0),0)) -> 0.0381 | E106: =IF(VLOOKUP($A106,값!$A:$W,MATCH(Main!E$1,값!$2:$2,0),0)="",NA(),VLOOKUP($A106,값!$A:$W,MATCH(Main!E$1,값!$2:$2,0),0)) -> -0.0058 | F106: =IF(VLOOKUP($A106,값!$A:$W,MATCH(Main!F$1,값!$2:$2,0),0)="",NA(),VLOOKUP($A106,값!$A:$W,MATCH(Main!F$1,값!$2:$2,0),0)) -> 0.0054 | G106: =IF(VLOOKUP($A106,값!$A:$W,MATCH(Main!G$1,값!$2:$2,0),0)="",NA(),VLOOKUP($A106,값!$A:$W,MATCH(Main!G$1,값!$2:$2,0),0)) -> -0.0058 | H106: =IF(VLOOKUP($A106,값!$A:$W,MATCH(Main!H$1,값!$2:$2,0),0)="",NA(),VLOOKUP($A106,값!$A:$W,MATCH(Main!H$1,값!$2:$2,0),0)) -> -0.0016 | I106: =IF(VLOOKUP($A106,값!$A:$W,MATCH(Main!I$1,값!$2:$2,0),0)="",NA(),VLOOKUP($A106,값!$A:$W,MATCH(Main!I$1,값!$2:$2,0),0)) -> 0.0114 | ... V106: =IF(VLOOKUP($A106,값!$A:$W,MATCH(Main!V$1,값!$2:$2,0),0)="",NA(),VLOOKUP($A106,값!$A:$W,MATCH(Main!V$1,값!$2:$2,0),0)) -> -0.0037779273
